Workbook

Sheet Well_Data
A1: WELL CONTROL TEST DATA — Test-1H (synthetic)
A2: Synthetic dataset for exercising a kill planner. Not from a real well. Blue = hardcoded input · Black = formula.
A4: Parameter | B4: Value | C4: Units | D4: Source / Note
A5: WELL AND RIG
A6: Well Name | B6: Test-1H (synthetic) | D6: Fictitious. Generated test data.
A7: Rig | B7: Land rig, triples
A8: Unit System | B8: Field (ft, in, ppg, psi, bbl)
A9: HOLE GEOMETRY
A10: Bit Depth (MD) | B10: 12500 | C10: ft | D10: Equals total tally length.
A11: Last Survey (MD) | B11: =MAX(Directional_Survey!$A$2:$A$158) -> 12460 | C11: ft | D11: Deepest survey station.
A12: Last Survey (TVD) | B12: =INDEX(Directional_Survey!$D$2:$D$158,MATCH(Well_Data!$B$11,Directional_Survey!$A$2:$A$158,0)) -> 10753.654 | C12: ft | D12: From survey sheet.
A13: Last Survey Inclination | B13: =INDEX(Directional_Survey!$B$2:$B$158,MATCH(Well_Data!$B$11,Directional_Survey!$A$2:$A$158,0)) -> 34.62 | C13: deg
A14: Bit Depth (TVD) | B14: =Well_Data!$B$12+(Well_Data!$B$10-Well_Data!$B$11)*COS(RADIANS(Well_Data!$B$13)) -> 10786.572 | C14: ft | D14: Extended below last station on last inclination.
A15: Kick-off Point (KOP) | B15: 2000 | C15: ft MD
A16: Build Rate | B16: 2.5 | C16: deg/100ft
A17: Hold Inclination | B17: 35 | C17: deg
A18: End of Build (EOB) | B18: =Well_Data!$B$15+Well_Data!$B$17/Well_Data!$B$16*100 -> 3400 | C18: ft MD
A19: CASING AND OPEN HOLE
A20: Surface Casing | B20: 13-3/8in 68.0 ppf K-55
A21: Surface Shoe (MD) | B21: 1800 | C21: ft
A22: Intermediate Casing | B22: 9-5/8in 47.0 ppf N-80 | D22: Governs MAASP — this is the exposed shoe.
A23: Intermediate Shoe (MD) | B23: 8200 | C23: ft | D23: A survey station is taken at this depth.
A24: Intermediate Shoe (TVD) | B24: =INDEX(Directional_Survey!$D$2:$D$158,MATCH(Well_Data!$B$23,Directional_Survey!$A$2:$A$158,0)) -> 7250.7045 | C24: ft | D24: Exact station lookup, no interpolation.
A25: Casing Drift ID | B25: 8.681 | C25: in | D25: 9-5/8in 47.0 ppf N-80.
A26: Open Hole Size | B26: 8.5 | C26: in
A27: MUD AND PUMP
A28: Mud Weight (current) | B28: 12.2 | C28: ppg
A29: Formation Integrity (LOT) | B29: 15.8 | C29: ppg EMW | D29: At intermediate shoe.
A30: Pump | B30: Triplex, 6.5in liner x 12.0in stroke, 95% eff
A31: Pump Liner | B31: 6.5 | C31: in
A32: Pump Stroke Length | B32: 12 | C32: in
A33: Pump Volumetric Efficiency | B33: 0.95
A34: Pump Output | B34: =0.000243*Well_Data!$B$31^2*Well_Data!$B$32*Well_Data!$B$33 -> 0.11704095 | C34: bbl/stk | D34: Triplex: 0.000243 x liner^2 x stroke x eff.
A35: Kill Rate | B35: 30 | C35: spm
A36: Slow Circulating Pressure | B36: 320 | C36: psi | D36: Measured at kill rate.
A37: Surface Line Volume | B37: 11.5 | C37: bbl | D37: Standpipe + hose + kelly. Excluded from strokes-to-bit.
A38: VOLUMES AND STROKES
A39: String Internal Volume | B39: =SUM(Volumes!$M$2:$M$406) -> 211.35461 | C39: bbl
A40: Annulus Volume — Open Hole | B40: =SUM(Volumes!$H$2:$H$406) -> 187.30696 | C40: bbl | D40: Shoe to bit.
A41: Annulus Volume — Inside Casing | B41: =SUM(Volumes!$J$2:$J$406) -> 401.15605 | C41: bbl | D41: Surface to shoe.
...

Sheet Pipe_Tally
A1: Item_No | B1: Joint_No | C1: Stand_No | D1: Description | E1: Component_Type | F1: OD_in | G1: ID_in | H1: Nominal_Weight_ppf | I1: Connection | J1: Length_ft | K1: Cum_Length_ft | L1: Top_Depth_ft | M1: Bottom_Depth_ft | N1: Capacity_bbl_per_ft | O1: Capacity_bbl | P1: Displacement_bbl_per_ft | Q1: Displacement_bbl
A2: 1 | D2: 8-1/2in PDC bit, 5x13 nozzles | E2: Bit | F2: 8.5 | G2: 3 | I2: 4-1/2 REG | J2: 1.02 | K2: =J2 -> 1.02 | L2: =Well_Data!$B$10-K2 -> 12498.98 | M2: =Well_Data!$B$10-K2+J2 -> 12500 | N2: =G2^2/1029.4 -> 0.0087429571 | O2: =N2*J2 -> 0.0089178162 | P2: =(F2^2-G2^2)/1029.4 -> 0.061443559 | Q2: =P2*J2 -> 0.062672431
A3: 2 | D3: 6-3/4in PD motor, 1.5 deg bent hsg | E3: Mud Motor | F3: 6.75 | G3: 3 | I3: NC50 | J3: 28.47 | K3: =K2+J3 -> 29.49 | L3: =Well_Data!$B$10-K3 -> 12470.51 | M3: =Well_Data!$B$10-K3+J3 -> 12498.98 | N3: =G3^2/1029.4 -> 0.0087429571 | O3: =N3*J3 -> 0.24891199 | P3: =(F3^2-G3^2)/1029.4 -> 0.035518263 | Q3: =P3*J3 -> 1.0112049
A4: 3 | D4: 8-1/4in near-bit stabilizer | E4: Stabilizer | F4: 8.25 | G4: 2.813 | I4: NC50 | J4: 5.52 | K4: =K3+J4 -> 35.01 | L4: =Well_Data!$B$10-K4 -> 12464.99 | M4: =Well_Data!$B$10-K4+J4 -> 12470.51 | N4: =G4^2/1029.4 -> 0.007686972 | O4: =N4*J4 -> 0.042432086 | P4: =(F4^2-G4^2)/1029.4 -> 0.058431641 | Q4: =P4*J4 -> 0.32254266
A5: 4 | D5: 6-3/4in MWD / gamma collar | E5: MWD | F5: 6.75 | G5: 3.25 | I5: NC50 | J5: 31.18 | K5: =K4+J5 -> 66.19 | L5: =Well_Data!$B$10-K5 -> 12433.81 | M5: =Well_Data!$B$10-K5+J5 -> 12464.99 | N5: =G5^2/1029.4 -> 0.010260832 | O5: =N5*J5 -> 0.31993273 | P5: =(F5^2-G5^2)/1029.4 -> 0.034000389 | Q5: =P5*J5 -> 1.0601321
A6: 5 | D6: 6-3/4in non-mag drill collar | E6: NMDC | F6: 6.75 | G6: 2.813 | I6: NC50 | J6: 30.14 | K6: =K5+J6 -> 96.33 | L6: =Well_Data!$B$10-K6 -> 12403.67 | M6: =Well_Data!$B$10-K6+J6 -> 12433.81 | N6: =G6^2/1029.4 -> 0.007686972 | O6: =N6*J6 -> 0.23168534 | P6: =(F6^2-G6^2)/1029.4 -> 0.036574248 | Q6: =P6*J6 -> 1.1023478
A7: 6 | D7: 8-1/4in string stabilizer | E7: Stabilizer | F7: 8.25 | G7: 2.813 | I7: NC50 | J7: 5.38 | K7: =K6+J7 -> 101.71 | L7: =Well_Data!$B$10-K7 -> 12398.29 | M7: =Well_Data!$B$10-K7+J7 -> 12403.67 | N7: =G7^2/1029.4 -> 0.007686972 | O7: =N7*J7 -> 0.041355909 | P7: =(F7^2-G7^2)/1029.4 -> 0.058431641 | Q7: =P7*J7 -> 0.31436223
A8: 7 | B8: 1 | D8: 6-3/4in drill collar #1 | E8: Drill Collar | F8: 6.75 | G8: 2.813 | H8: 99 | I8: NC50 | J8: 30.4 | K8: =K7+J8 -> 132.11 | L8: =Well_Data!$B$10-K8 -> 12367.89 | M8: =Well_Data!$B$10-K8+J8 -> 12398.29 | N8: =G8^2/1029.4 -> 0.007686972 | O8: =N8*J8 -> 0.23368395 | P8: =(F8^2-G8^2)/1029.4 -> 0.036574248 | Q8: =P8*J8 -> 1.1118571
A9: 8 | B9: 2 | D9: 6-3/4in drill collar #2 | E9: Drill Collar | F9: 6.75 | G9: 2.813 | H9: 99 | I9: NC50 | J9: 30.42 | K9: =K8+J9 -> 162.53 | L9: =Well_Data!$B$10-K9 -> 12337.47 | M9: =Well_Data!$B$10-K9+J9 -> 12367.89 | N9: =G9^2/1029.4 -> 0.007686972 | O9: =N9*J9 -> 0.23383769 | P9: =(F9^2-G9^2)/1029.4 -> 0.036574248 | Q9: =P9*J9 -> 1.1125886
A10: 9 | B10: 3 | D10: 6-3/4in drill collar #3 | E10: Drill Collar | F10: 6.75 | G10: 2.813 | H10: 99 | I10: NC50 | J10: 30.22 | K10: =K9+J10 -> 192.75 | L10: =Well_Data!$B$10-K10 -> 12307.25 | M10: =Well_Data!$B$10-K10+J10 -> 12337.47 | N10: =G10^2/1029.4 -> 0.007686972 | O10: =N10*J10 -> 0.23230029 | P10: =(F10^2-G10^2)/1029.4 -> 0.036574248 | Q10: =P10*J10 -> 1.1052738
A11: 10 | B11: 4 | D11: 6-3/4in drill collar #4 | E11: Drill Collar | F11: 6.75 | G11: 2.813 | H11: 99 | I11: NC50 | J11: 30.27 | K11: =K10+J11 -> 223.02 | L11: =Well_Data!$B$10-K11 -> 12276.98 | M11: =Well_Data!$B$10-K11+J11 -> 12307.25 | N11: =G11^2/1029.4 -> 0.007686972 | O11: =N11*J11 -> 0.23268464 | P11: =(F11^2-G11^2)/1029.4 -> 0.036574248 | Q11: =P11*J11 -> 1.1071025
A12: 11 | B12: 5 | D12: 6-3/4in drill collar #5 | E12: Drill Collar | F12: 6.75 | G12: 2.813 | H12: 99 | I12: NC50 | J12: 30.17 | K12: =K11+J12 -> 253.19 | L12: =Well_Data!$B$10-K12 -> 12246.81 | M12: =Well_Data!$B$10-K12+J12 -> 12276.98 | N12: =G12^2/1029.4 -> 0.007686972 | O12: =N12*J12 -> 0.23191595 | P12: =(F12^2-G12^2)/1029.4 -> 0.036574248 | Q12: =P12*J12 -> 1.1034451
A13: 12 | B13: 6 | D13: 6-3/4in drill collar #6 | E13: Drill Collar | F13: 6.75 | G13: 2.813 | H13: 99 | I13: NC50 | J13: 30.31 | K13: =K12+J13 -> 283.5 | L13: =Well_Data!$B$10-K13 -> 12216.5 | M13: =Well_Data!$B$10-K13+J13 -> 12246.81 | N13: =G13^2/1029.4 -> 0.007686972 | O13: =N13*J13 -> 0.23299212 | P13: =(F13^2-G13^2)/1029.4 -> 0.036574248 | Q13: =P13*J13 -> 1.1085655
A14: 13 | B14: 7 | D14: 6-3/4in drill collar #7 | E14: Drill Collar | F14: 6.75 | G14: 2.813 | H14: 99 | I14: NC50 | J14: 30.08 | K14: =K13+J14 -> 313.58 | L14: =Well_Data!$B$10-K14 -> 12186.42 | M14: =Well_Data!$B$10-K14+J14 -> 12216.5 | N14: =G14^2/1029.4 -> 0.007686972 | O14: =N14*J14 -> 0.23122412 | P14: =(F14^2-G14^2)/1029.4 -> 0.036574248 | Q14: =P14*J14 -> 1.1001534
A15: 14 | B15: 8 | D15: 6-3/4in drill collar #8 | E15: Drill Collar | F15: 6.75 | G15: 2.813 | H15: 99 | I15: NC50 | J15: 30.23 | K15: =K14+J15 -> 343.81 | L15: =Well_Data!$B$10-K15 -> 12156.19 | M15: =Well_Data!$B$10-K15+J15 -> 12186.42 | N15: =G15^2/1029.4 -> 0.007686972 | O15: =N15*J15 -> 0.23237716 | P15: =(F15^2-G15^2)/1029.4 -> 0.036574248 | Q15: =P15*J15 -> 1.1056395
A16: 15 | B16: 9 | D16: 6-3/4in drill collar #9 | E16: Drill Collar | F16: 6.75 | G16: 2.813 | H16: 99 | I16: NC50 | J16: 30.11 | K16: =K15+J16 -> 373.92 | L16: =Well_Data!$B$10-K16 -> 12126.08 | M16: =Well_Data!$B$10-K16+J16 -> 12156.19 | N16: =G16^2/1029.4 -> 0.007686972 | O16: =N16*J16 -> 0.23145473 | P16: =(F16^2-G16^2)/1029.4 -> 0.036574248 | Q16: =P16*J16 -> 1.1012506
A17: 16 | B17: 10 | D17: 6-3/4in drill collar #10 | E17: Drill Collar | F17: 6.75 | G17: 2.813 | H17: 99 | I17: NC50 | J17: 30.07 | K17: =K16+J17 -> 403.99 | L17: =Well_Data!$B$10-K17 -> 12096.01 | M17: =Well_Data!$B$10-K17+J17 -> 12126.08 | N17: =G17^2/1029.4 -> 0.007686972 | O17: =N17*J17 -> 0.23114725 | P17: =(F17^2-G17^2)/1029.4 -> 0.036574248 | Q17: =P17*J17 -> 1.0997876
A18: 17 | B18: 11 | D18: 6-3/4in drill collar #11 | E18: Drill Collar | F18: 6.75 | G18: 2.813 | H18: 99 | I18: NC50 | J18: 30.25 | K18: =K17+J18 -> 434.24 | L18: =Well_Data!$B$10-K18 -> 12065.76 | M18: =Well_Data!$B$10-K18+J18 -> 12096.01 | N18: =G18^2/1029.4 -> 0.007686972 | O18: =N18*J18 -> 0.2325309 | P18: =(F18^2-G18^2)/1029.4 -> 0.036574248 | Q18: =P18*J18 -> 1.106371
A19: 18 | B19: 12 | D19: 6-3/4in drill collar #12 | E19: Drill Collar | F19: 6.75 | G19: 2.813 | H19: 99 | I19: NC50 | J19: 30.35 | K19: =K18+J19 -> 464.59 | L19: =Well_Data!$B$10-K19 -> 12035.41 | M19: =Well_Data!$B$10-K19+J19 -> 12065.76 | N19: =G19^2/1029.4 -> 0.007686972 | O19: =N19*J19 -> 0.2332996 | P19: =(F19^2-G19^2)/1029.4 -> 0.036574248 | Q19: =P19*J19 -> 1.1100284
A20: 19 | D20: 6-1/2in hydraulic drilling jar | E20: Jar | F20: 6.5 | G20: 2.75 | I20: NC50 | J20: 31.05 | K20: =K19+J20 -> 495.64 | L20: =Well_Data!$B$10-K20 -> 12004.36 | M20: =Well_Data!$B$10-K20+J20 -> 12035.41 | N20: =G20^2/1029.4 -> 0.0073465125 | O20: =N20*J20 -> 0.22810921 | P20: =(F20^2-G20^2)/1029.4 -> 0.033696814 | Q20: =P20*J20 -> 1.0462861
A21: 20 | B21: 13 | D21: 5in HWDP, 49.3 ppf #1 | E21: HWDP | F21: 5 | G21: 3 | H21: 49.3 | I21: NC50 | J21: 30.43 | K21: =K20+J21 -> 526.07 | L21: =Well_Data!$B$10-K21 -> 11973.93 | M21: =Well_Data!$B$10-K21+J21 -> 12004.36 | N21: =G21^2/1029.4 -> 0.0087429571 | O21: =N21*J21 -> 0.26604818 | P21: =(F21^2-G21^2)/1029.4 -> 0.015543035 | Q21: =P21*J21 -> 0.47297455
A22: 21 | B22: 14 | D22: 5in HWDP, 49.3 ppf #2 | E22: HWDP | F22: 5 | G22: 3 | H22: 49.3 | I22: NC50 | J22: 30.69 | K22: =K21+J22 -> 556.76 | L22: =Well_Data!$B$10-K22 -> 11943.24 | M22: =Well_Data!$B$10-K22+J22 -> 11973.93 | N22: =G22^2/1029.4 -> 0.0087429571 | O22: =N22*J22 -> 0.26832135 | P22: =(F22^2-G22^2)/1029.4 -> 0.015543035 | Q22: =P22*J22 -> 0.47701574
A23: 22 | B23: 15 | D23: 5in HWDP, 49.3 ppf #3 | E23: HWDP | F23: 5 | G23: 3 | H23: 49.3 | I23: NC50 | J23: 30.59 | K23: =K22+J23 -> 587.35 | L23: =Well_Data!$B$10-K23 -> 11912.65 | M23: =Well_Data!$B$10-K23+J23 -> 11943.24 | N23: =G23^2/1029.4 -> 0.0087429571 | O23: =N23*J23 -> 0.26744706 | P23: =(F23^2-G23^2)/1029.4 -> 0.015543035 | Q23: =P23*J23 -> 0.47546143
A24: 23 | B24: 16 | D24: 5in HWDP, 49.3 ppf #4 | E24: HWDP | F24: 5 | G24: 3 | H24: 49.3 | I24: NC50 | J24: 30.56 | K24: =K23+J24 -> 617.91 | L24: =Well_Data!$B$10-K24 -> 11882.09 | M24: =Well_Data!$B$10-K24+J24 -> 11912.65 | N24: =G24^2/1029.4 -> 0.0087429571 | O24: =N24*J24 -> 0.26718477 | P24: =(F24^2-G24^2)/1029.4 -> 0.015543035 | Q24: =P24*J24 -> 0.47499514
A25: 24 | B25: 17 | D25: 5in HWDP, 49.3 ppf #5 | E25: HWDP | F25: 5 | G25: 3 | H25: 49.3 | I25: NC50 | J25: 30.68 | K25: =K24+J25 -> 648.59 | L25: =Well_Data!$B$10-K25 -> 11851.41 | M25: =Well_Data!$B$10-K25+J25 -> 11882.09 | N25: =G25^2/1029.4 -> 0.0087429571 | O25: =N25*J25 -> 0.26823392 | P25: =(F25^2-G25^2)/1029.4 -> 0.015543035 | Q25: =P25*J25 -> 0.47686031
A26: 25 | B26: 18 | D26: 5in HWDP, 49.3 ppf #6 | E26: HWDP | F26: 5 | G26: 3 | H26: 49.3 | I26: NC50 | J26: 30.47 | K26: =K25+J26 -> 679.06 | L26: =Well_Data!$B$10-K26 -> 11820.94 | M26: =Well_Data!$B$10-K26+J26 -> 11851.41 | N26: =G26^2/1029.4 -> 0.0087429571 | O26: =N26*J26 -> 0.2663979 | P26: =(F26^2-G26^2)/1029.4 -> 0.015543035 | Q26: =P26*J26 -> 0.47359627
A27: 26 | B27: 19 | D27: 5in HWDP, 49.3 ppf #7 | E27: HWDP | F27: 5 | G27: 3 | H27: 49.3 | I27: NC50 | J27: 30.4 | K27: =K26+J27 -> 709.46 | L27: =Well_Data!$B$10-K27 -> 11790.54 | M27: =Well_Data!$B$10-K27+J27 -> 11820.94 | N27: =G27^2/1029.4 -> 0.0087429571 | O27: =N27*J27 -> 0.26578589 | P27: =(F27^2-G27^2)/1029.4 -> 0.015543035 | Q27: =P27*J27 -> 0.47250826
A28: 27 | B28: 20 | D28: 5in HWDP, 49.3 ppf #8 | E28: HWDP | F28: 5 | G28: 3 | H28: 49.3 | I28: NC50 | J28: 30.35 | K28: =K27+J28 -> 739.81 | L28: =Well_Data!$B$10-K28 -> 11760.19 | M28: =Well_Data!$B$10-K28+J28 -> 11790.54 | N28: =G28^2/1029.4 -> 0.0087429571 | O28: =N28*J28 -> 0.26534875 | P28: =(F28^2-G28^2)/1029.4 -> 0.015543035 | Q28: =P28*J28 -> 0.47173111
A29: 28 | B29: 21 | D29: 5in HWDP, 49.3 ppf #9 | E29: HWDP | F29: 5 | G29: 3 | H29: 49.3 | I29: NC50 | J29: 30.56 | K29: =K28+J29 -> 770.37 | L29: =Well_Data!$B$10-K29 -> 11729.63 | M29: =Well_Data!$B$10-K29+J29 -> 11760.19 | N29: =G29^2/1029.4 -> 0.0087429571 | O29: =N29*J29 -> 0.26718477 | P29: =(F29^2-G29^2)/1029.4 -> 0.015543035 | Q29: =P29*J29 -> 0.47499514
A30: 29 | B30: 22 | D30: 5in HWDP, 49.3 ppf #10 | E30: HWDP | F30: 5 | G30: 3 | H30: 49.3 | I30: NC50 | J30: 30.32 | K30: =K29+J30 -> 800.69 | L30: =Well_Data!$B$10-K30 -> 11699.31 | M30: =Well_Data!$B$10-K30+J30 -> 11729.63 | N30: =G30^2/1029.4 -> 0.0087429571 | O30: =N30*J30 -> 0.26508646 | P30: =(F30^2-G30^2)/1029.4 -> 0.015543035 | Q30: =P30*J30 -> 0.47126481
A31: 30 | B31: 23 | D31: 5in HWDP, 49.3 ppf #11 | E31: HWDP | F31: 5 | G31: 3 | H31: 49.3 | I31: NC50 | J31: 30.66 | K31: =K30+J31 -> 831.35 | L31: =Well_Data!$B$10-K31 -> 11668.65 | M31: =Well_Data!$B$10-K31+J31 -> 11699.31 | N31: =G31^2/1029.4 -> 0.0087429571 | O31: =N31*J31 -> 0.26805906 | P31: =(F31^2-G31^2)/1029.4 -> 0.015543035 | Q31: =P31*J31 -> 0.47654945
A32: 31 | B32: 24 | D32: 5in HWDP, 49.3 ppf #12 | E32: HWDP | F32: 5 | G32: 3 | H32: 49.3 | I32: NC50 | J32: 30.3 | K32: =K31+J32 -> 861.65 | L32: =Well_Data!$B$10-K32 -> 11638.35 | M32: =Well_Data!$B$10-K32+J32 -> 11668.65 | N32: =G32^2/1029.4 -> 0.0087429571 | O32: =N32*J32 -> 0.2649116 | P32: =(F32^2-G32^2)/1029.4 -> 0.015543035 | Q32: =P32*J32 -> 0.47095395
... A41: 40 | B41: 33 | D41: 5in HWDP, 49.3 ppf #21 | E41: HWDP | F41: 5 | G41: 3 | H41: 49.3 | I41: NC50 | J41: 30.65 | K41: =K40+J41 -> 1136.21 | L41: =Well_Data!$B$10-K41 -> 11363.79 | M41: =Well_Data!$B$10-K41+J41 -> 11394.44 | N41: =G41^2/1029.4 -> 0.0087429571 | O41: =N41*J41 -> 0.26797163 | P41: =(F41^2-G41^2)/1029.4 -> 0.015543035 | Q41: =P41*J41 -> 0.47639402
A42: 41 | B42: 34 | C42: 1 | D42: 5in 19.50 ppf S-135 drill pipe | E42: Drill Pipe | F42: 5 | G42: 4.276 | H42: 19.5 | I42: NC50 (5-1/2 FH) | J42: 31.3 | K42: =K41+J42 -> 1167.51 | L42: =Well_Data!$B$10-K42 -> 11332.49 | M42: =Well_Data!$B$10-K42+J42 -> 11363.79 | N42: =G42^2/1029.4 -> 0.017761974 | O42: =N42*J42 -> 0.55594979 | P42: =(F42^2-G42^2)/1029.4 -> 0.0065240179 | Q42: =P42*J42 -> 0.20420176
A43: 42 | B43: 35 | C43: 1 | D43: 5in 19.50 ppf S-135 drill pipe | E43: Drill Pipe | F43: 5 | G43: 4.276 | H43: 19.5 | I43: NC50 (5-1/2 FH) | J43: 31.28 | K43: =K42+J43 -> 1198.79 | L43: =Well_Data!$B$10-K43 -> 11301.21 | M43: =Well_Data!$B$10-K43+J43 -> 11332.49 | N43: =G43^2/1029.4 -> 0.017761974 | O43: =N43*J43 -> 0.55559455 | P43: =(F43^2-G43^2)/1029.4 -> 0.0065240179 | Q43: =P43*J43 -> 0.20407128
A44: 43 | B44: 36 | C44: 1 | D44: 5in 19.50 ppf S-135 drill pipe | E44: Drill Pipe | F44: 5 | G44: 4.276 | H44: 19.5 | I44: NC50 (5-1/2 FH) | J44: 31.24 | K44: =K43+J44 -> 1230.03 | L44: =Well_Data!$B$10-K44 -> 11269.97 | M44: =Well_Data!$B$10-K44+J44 -> 11301.21 | N44: =G44^2/1029.4 -> 0.017761974 | O44: =N44*J44 -> 0.55488407 | P44: =(F44^2-G44^2)/1029.4 -> 0.0065240179 | Q44: =P44*J44 -> 0.20381032
A45: 44 | B45: 37 | C45: 2 | D45: 5in 19.50 ppf S-135 drill pipe | E45: Drill Pipe | F45: 5 | G45: 4.276 | H45: 19.5 | I45: NC50 (5-1/2 FH) | J45: 31.47 | K45: =K44+J45 -> 1261.5 | L45: =Well_Data!$B$10-K45 -> 11238.5 | M45: =Well_Data!$B$10-K45+J45 -> 11269.97 | N45: =G45^2/1029.4 -> 0.017761974 | O45: =N45*J45 -> 0.55896932 | P45: =(F45^2-G45^2)/1029.4 -> 0.0065240179 | Q45: =P45*J45 -> 0.20531084
A46: 45 | B46: 38 | C46: 2 | D46: 5in 19.50 ppf S-135 drill pipe | E46: Drill Pipe | F46: 5 | G46: 4.276 | H46: 19.5 | I46: NC50 (5-1/2 FH) | J46: 31.11 | K46: =K45+J46 -> 1292.61 | L46: =Well_Data!$B$10-K46 -> 11207.39 | M46: =Well_Data!$B$10-K46+J46 -> 11238.5 | N46: =G46^2/1029.4 -> 0.017761974 | O46: =N46*J46 -> 0.55257501 | P46: =(F46^2-G46^2)/1029.4 -> 0.0065240179 | Q46: =P46*J46 -> 0.2029622
A47: 46 | B47: 39 | C47: 2 | D47: 5in 19.50 ppf S-135 drill pipe | E47: Drill Pipe | F47: 5 | G47: 4.276 | H47: 19.5 | I47: NC50 (5-1/2 FH) | J47: 31.12 | K47: =K46+J47 -> 1323.73 | L47: =Well_Data!$B$10-K47 -> 11176.27 | M47: =Well_Data!$B$10-K47+J47 -> 11207.39 | N47: =G47^2/1029.4 -> 0.017761974 | O47: =N47*J47 -> 0.55275263 | P47: =(F47^2-G47^2)/1029.4 -> 0.0065240179 | Q47: =P47*J47 -> 0.20302744
A48: 47 | B48: 40 | C48: 3 | D48: 5in 19.50 ppf S-135 drill pipe | E48: Drill Pipe | F48: 5 | G48: 4.276 | H48: 19.5 | I48: NC50 (5-1/2 FH) | J48: 31.17 | K48: =K47+J48 -> 1354.9 | L48: =Well_Data!$B$10-K48 -> 11145.1 | M48: =Well_Data!$B$10-K48+J48 -> 11176.27 | N48: =G48^2/1029.4 -> 0.017761974 | O48: =N48*J48 -> 0.55364073 | P48: =(F48^2-G48^2)/1029.4 -> 0.0065240179 | Q48: =P48*J48 -> 0.20335364
...

Sheet Directional_Survey
A1: MD_ft | B1: Inclination_deg | C1: Azimuth_deg | D1: TVD_ft | E1: Northing_ft | F1: Easting_ft | G1: DLS_deg_per_100ft | H1: Course_Length_ft | I1: Vertical_Section_ft | J1: Closure_Distance_ft | K1: Closure_Azimuth_deg
A2: 0 | B2: 0 | C2: 0 | D2: 0 | E2: 0 | F2: 0 | G2: 0 | H2: 0 | I2: =J2*COS(RADIANS(K2-Well_Data!$B$68)) -> 0 | J2: =SQRT(E2^2+F2^2) -> 0 | K2: =IF(J2=0,0,MOD(DEGREES(ATAN2(E2,F2)),360)) -> 0
A3: 200 | B3: 0 | C3: 0 | D3: =D2+(A3-A2)/2*(COS(RADIANS(B2))+COS(RADIANS(B3)))*(IF(ACOS(MIN(1,MAX(-1,COS(RADIANS(B3-B2))-SIN(RADIANS(B2))*SIN(RADIANS(B3))*(1-COS(RADIANS(C3-C2))))))=0,1,2/(ACOS(MIN(1,MAX(-1,COS(RADIANS(B3-B2))-SIN(RADIANS(B2))*SIN(RADIANS(B3))*(1-COS(RADIANS(C3-C2)))))))*TAN((ACOS(MIN(1,MAX(-1,COS(RADIANS(B3-B2))-SIN(RADIANS(B2))*SIN(RADIANS(B3))*(1-COS(RADIANS(C3-C2)))))))/2))) -> 200 | E3: =E2+(A3-A2)/2*(SIN(RADIANS(B2))*COS(RADIANS(C2))+SIN(RADIANS(B3))*COS(RADIANS(C3)))*(IF(ACOS(MIN(1,MAX(-1,COS(RADIANS(B3-B2))-SIN(RADIANS(B2))*SIN(RADIANS(B3))*(1-COS(RADIANS(C3-C2))))))=0,1,2/(ACOS(MIN(1,MAX(-1,COS(RADIANS(B3-B2))-SIN(RADIANS(B2))*SIN(RADIANS(B3))*(1-COS(RADIANS(C3-C2)))))))*TAN((ACOS(MIN(1,MAX(-1,COS(RADIANS(B3-B2))-SIN(RADIANS(B2))*SIN(RADIANS(B3))*(1-COS(RADIANS(C3-C2)))))))/2))) -> 0 | F3: =F2+(A3-A2)/2*(SIN(RADIANS(B2))*SIN(RADIANS(C2))+SIN(RADIANS(B3))*SIN(RADIANS(C3)))*(IF(ACOS(MIN(1,MAX(-1,COS(RADIANS(B3-B2))-SIN(RADIANS(B2))*SIN(RADIANS(B3))*(1-COS(RADIANS(C3-C2))))))=0,1,2/(ACOS(MIN(1,MAX(-1,COS(RADIANS(B3-B2))-SIN(RADIANS(B2))*SIN(RADIANS(B3))*(1-COS(RADIANS(C3-C2)))))))*TAN((ACOS(MIN(1,MAX(-1,COS(RADIANS(B3-B2))-SIN(RADIANS(B2))*SIN(RADIANS(B3))*(1-COS(RADIANS(C3-C2)))))))/2))) -> 0 | G3: =IF(H3=0,0,DEGREES(ACOS(MIN(1,MAX(-1,COS(RADIANS(B3-B2))-SIN(RADIANS(B2))*SIN(RADIANS(B3))*(1-COS(RADIANS(C3-C2)))))))*100/H3) -> 0 | H3: =A3-A2 -> 200 | I3: =J3*COS(RADIANS(K3-Well_Data!$B$68)) -> 0 | J3: =SQRT(E3^2+F3^2) -> 0 | K3: =IF(J3=0,0,MOD(DEGREES(ATAN2(E3,F3)),360)) -> 0
A4: 400 | B4: 0 | C4: 0 | D4: =D3+(A4-A3)/2*(COS(RADIANS(B3))+COS(RADIANS(B4)))*(IF(ACOS(MIN(1,MAX(-1,COS(RADIANS(B4-B3))-SIN(RADIANS(B3))*SIN(RADIANS(B4))*(1-COS(RADIANS(C4-C3))))))=0,1,2/(ACOS(MIN(1,MAX(-1,COS(RADIANS(B4-B3))-SIN(RADIANS(B3))*SIN(RADIANS(B4))*(1-COS(RADIANS(C4-C3)))))))*TAN((ACOS(MIN(1,MAX(-1,COS(RADIANS(B4-B3))-SIN(RADIANS(B3))*SIN(RADIANS(B4))*(1-COS(RADIANS(C4-C3)))))))/2))) -> 400 | E4: =E3+(A4-A3)/2*(SIN(RADIANS(B3))*COS(RADIANS(C3))+SIN(RADIANS(B4))*COS(RADIANS(C4)))*(IF(ACOS(MIN(1,MAX(-1,COS(RADIANS(B4-B3))-SIN(RADIANS(B3))*SIN(RADIANS(B4))*(1-COS(RADIANS(C4-C3))))))=0,1,2/(ACOS(MIN(1,MAX(-1,COS(RADIANS(B4-B3))-SIN(RADIANS(B3))*SIN(RADIANS(B4))*(1-COS(RADIANS(C4-C3)))))))*TAN((ACOS(MIN(1,MAX(-1,COS(RADIANS(B4-B3))-SIN(RADIANS(B3))*SIN(RADIANS(B4))*(1-COS(RADIANS(C4-C3)))))))/2))) -> 0 | F4: =F3+(A4-A3)/2*(SIN(RADIANS(B3))*SIN(RADIANS(C3))+SIN(RADIANS(B4))*SIN(RADIANS(C4)))*(IF(ACOS(MIN(1,MAX(-1,COS(RADIANS(B4-B3))-SIN(RADIANS(B3))*SIN(RADIANS(B4))*(1-COS(RADIANS(C4-C3))))))=0,1,2/(ACOS(MIN(1,MAX(-1,COS(RADIANS(B4-B3))-SIN(RADIANS(B3))*SIN(RADIANS(B4))*(1-COS(RADIANS(C4-C3)))))))*TAN((ACOS(MIN(1,MAX(-1,COS(RADIANS(B4-B3))-SIN(RADIANS(B3))*SIN(RADIANS(B4))*(1-COS(RADIANS(C4-C3)))))))/2))) -> 0 | G4: =IF(H4=0,0,DEGREES(ACOS(MIN(1,MAX(-1,COS(RADIANS(B4-B3))-SIN(RADIANS(B3))*SIN(RADIANS(B4))*(1-COS(RADIANS(C4-C3)))))))*100/H4) -> 0 | H4: =A4-A3 -> 200 | I4: =J4*COS(RADIANS(K4-Well_Data!$B$68)) -> 0 | J4: =SQRT(E4^2+F4^2) -> 0 | K4: =IF(J4=0,0,MOD(DEGREES(ATAN2(E4,F4)),360)) -> 0
A5: 600 | B5: 0 | C5: 0 | D5: =D4+(A5-A4)/2*(COS(RADIANS(B4))+COS(RADIANS(B5)))*(IF(ACOS(MIN(1,MAX(-1,COS(RADIANS(B5-B4))-SIN(RADIANS(B4))*SIN(RADIANS(B5))*(1-COS(RADIANS(C5-C4))))))=0,1,2/(ACOS(MIN(1,MAX(-1,COS(RADIANS(B5-B4))-SIN(RADIANS(B4))*SIN(RADIANS(B5))*(1-COS(RADIANS(C5-C4)))))))*TAN((ACOS(MIN(1,MAX(-1,COS(RADIANS(B5-B4))-SIN(RADIANS(B4))*SIN(RADIANS(B5))*(1-COS(RADIANS(C5-C4)))))))/2))) -> 600 | E5: =E4+(A5-A4)/2*(SIN(RADIANS(B4))*COS(RADIANS(C4))+SIN(RADIANS(B5))*COS(RADIANS(C5)))*(IF(ACOS(MIN(1,MAX(-1,COS(RADIANS(B5-B4))-SIN(RADIANS(B4))*SIN(RADIANS(B5))*(1-COS(RADIANS(C5-C4))))))=0,1,2/(ACOS(MIN(1,MAX(-1,COS(RADIANS(B5-B4))-SIN(RADIANS(B4))*SIN(RADIANS(B5))*(1-COS(RADIANS(C5-C4)))))))*TAN((ACOS(MIN(1,MAX(-1,COS(RADIANS(B5-B4))-SIN(RADIANS(B4))*SIN(RADIANS(B5))*(1-COS(RADIANS(C5-C4)))))))/2))) -> 0 | F5: =F4+(A5-A4)/2*(SIN(RADIANS(B4))*SIN(RADIANS(C4))+SIN(RADIANS(B5))*SIN(RADIANS(C5)))*(IF(ACOS(MIN(1,MAX(-1,COS(RADIANS(B5-B4))-SIN(RADIANS(B4))*SIN(RADIANS(B5))*(1-COS(RADIANS(C5-C4))))))=0,1,2/(ACOS(MIN(1,MAX(-1,COS(RADIANS(B5-B4))-SIN(RADIANS(B4))*SIN(RADIANS(B5))*(1-COS(RADIANS(C5-C4)))))))*TAN((ACOS(MIN(1,MAX(-1,COS(RADIANS(B5-B4))-SIN(RADIANS(B4))*SIN(RADIANS(B5))*(1-COS(RADIANS(C5-C4)))))))/2))) -> 0 | G5: =IF(H5=0,0,DEGREES(ACOS(MIN(1,MAX(-1,COS(RADIANS(B5-B4))-SIN(RADIANS(B4))*SIN(RADIANS(B5))*(1-COS(RADIANS(C5-C4)))))))*100/H5) -> 0 | H5: =A5-A4 -> 200 | I5: =J5*COS(RADIANS(K5-Well_Data!$B$68)) -> 0 | J5: =SQRT(E5^2+F5^2) -> 0 | K5: =IF(J5=0,0,MOD(DEGREES(ATAN2(E5,F5)),360)) -> 0
A6: 800 | B6: 0 | C6: 0 | D6: =D5+(A6-A5)/2*(COS(RADIANS(B5))+COS(RADIANS(B6)))*(IF(ACOS(MIN(1,MAX(-1,COS(RADIANS(B6-B5))-SIN(RADIANS(B5))*SIN(RADIANS(B6))*(1-COS(RADIANS(C6-C5))))))=0,1,2/(ACOS(MIN(1,MAX(-1,COS(RADIANS(B6-B5))-SIN(RADIANS(B5))*SIN(RADIANS(B6))*(1-COS(RADIANS(C6-C5)))))))*TAN((ACOS(MIN(1,MAX(-1,COS(RADIANS(B6-B5))-SIN(RADIANS(B5))*SIN(RADIANS(B6))*(1-COS(RADIANS(C6-C5)))))))/2))) -> 800 | E6: =E5+(A6-A5)/2*(SIN(RADIANS(B5))*COS(RADIANS(C5))+SIN(RADIANS(B6))*COS(RADIANS(C6)))*(IF(ACOS(MIN(1,MAX(-1,COS(RADIANS(B6-B5))-SIN(RADIANS(B5))*SIN(RADIANS(B6))*(1-COS(RADIANS(C6-C5))))))=0,1,2/(ACOS(MIN(1,MAX(-1,COS(RADIANS(B6-B5))-SIN(RADIANS(B5))*SIN(RADIANS(B6))*(1-COS(RADIANS(C6-C5)))))))*TAN((ACOS(MIN(1,MAX(-1,COS(RADIANS(B6-B5))-SIN(RADIANS(B5))*SIN(RADIANS(B6))*(1-COS(RADIANS(C6-C5)))))))/2))) -> 0 | F6: =F5+(A6-A5)/2*(SIN(RADIANS(B5))*SIN(RADIANS(C5))+SIN(RADIANS(B6))*SIN(RADIANS(C6)))*(IF(ACOS(MIN(1,MAX(-1,COS(RADIANS(B6-B5))-SIN(RADIANS(B5))*SIN(RADIANS(B6))*(1-COS(RADIANS(C6-C5))))))=0,1,2/(ACOS(MIN(1,MAX(-1,COS(RADIANS(B6-B5))-SIN(RADIANS(B5))*SIN(RADIANS(B6))*(1-COS(RADIANS(C6-C5)))))))*TAN((ACOS(MIN(1,MAX(-1,COS(RADIANS(B6-B5))-SIN(RADIANS(B5))*SIN(RADIANS(B6))*(1-COS(RADIANS(C6-C5)))))))/2))) -> 0 | G6: =IF(H6=0,0,DEGREES(ACOS(MIN(1,MAX(-1,COS(RADIANS(B6-B5))-SIN(RADIANS(B5))*SIN(RADIANS(B6))*(1-COS(RADIANS(C6-C5)))))))*100/H6) -> 0 | H6: =A6-A5 -> 200 | I6: =J6*COS(RADIANS(K6-Well_Data!$B$68)) -> 0 | J6: =SQRT(E6^2+F6^2) -> 0 | K6: =IF(J6=0,0,MOD(DEGREES(ATAN2(E6,F6)),360)) -> 0
A7: 1000 | B7: 0 | C7: 0 | D7: =D6+(A7-A6)/2*(COS(RADIANS(B6))+COS(RADIANS(B7)))*(IF(ACOS(MIN(1,MAX(-1,COS(RADIANS(B7-B6))-SIN(RADIANS(B6))*SIN(RADIANS(B7))*(1-COS(RADIANS(C7-C6))))))=0,1,2/(ACOS(MIN(1,MAX(-1,COS(RADIANS(B7-B6))-SIN(RADIANS(B6))*SIN(RADIANS(B7))*(1-COS(RADIANS(C7-C6)))))))*TAN((ACOS(MIN(1,MAX(-1,COS(RADIANS(B7-B6))-SIN(RADIANS(B6))*SIN(RADIANS(B7))*(1-COS(RADIANS(C7-C6)))))))/2))) -> 1000 | E7: =E6+(A7-A6)/2*(SIN(RADIANS(B6))*COS(RADIANS(C6))+SIN(RADIANS(B7))*COS(RADIANS(C7)))*(IF(ACOS(MIN(1,MAX(-1,COS(RADIANS(B7-B6))-SIN(RADIANS(B6))*SIN(RADIANS(B7))*(1-COS(RADIANS(C7-C6))))))=0,1,2/(ACOS(MIN(1,MAX(-1,COS(RADIANS(B7-B6))-SIN(RADIANS(B6))*SIN(RADIANS(B7))*(1-COS(RADIANS(C7-C6)))))))*TAN((ACOS(MIN(1,MAX(-1,COS(RADIANS(B7-B6))-SIN(RADIANS(B6))*SIN(RADIANS(B7))*(1-COS(RADIANS(C7-C6)))))))/2))) -> 0 | F7: =F6+(A7-A6)/2*(SIN(RADIANS(B6))*SIN(RADIANS(C6))+SIN(RADIANS(B7))*SIN(RADIANS(C7)))*(IF(ACOS(MIN(1,MAX(-1,COS(RADIANS(B7-B6))-SIN(RADIANS(B6))*SIN(RADIANS(B7))*(1-COS(RADIANS(C7-C6))))))=0,1,2/(ACOS(MIN(1,MAX(-1,COS(RADIANS(B7-B6))-SIN(RADIANS(B6))*SIN(RADIANS(B7))*(1-COS(RADIANS(C7-C6)))))))*TAN((ACOS(MIN(1,MAX(-1,COS(RADIANS(B7-B6))-SIN(RADIANS(B6))*SIN(RADIANS(B7))*(1-COS(RADIANS(C7-C6)))))))/2))) -> 0 | G7: =IF(H7=0,0,DEGREES(ACOS(MIN(1,MAX(-1,COS(RADIANS(B7-B6))-SIN(RADIANS(B6))*SIN(RADIANS(B7))*(1-COS(RADIANS(C7-C6)))))))*100/H7) -> 0 | H7: =A7-A6 -> 200 | I7: =J7*COS(RADIANS(K7-Well_Data!$B$68)) -> 0 | J7: =SQRT(E7^2+F7^2) -> 0 | K7: =IF(J7=0,0,MOD(DEGREES(ATAN2(E7,F7)),360)) -> 0
A8: 1200 | B8: 0 | C8: 0 | D8: =D7+(A8-A7)/2*(COS(RADIANS(B7))+COS(RADIANS(B8)))*(IF(ACOS(MIN(1,MAX(-1,COS(RADIANS(B8-B7))-SIN(RADIANS(B7))*SIN(RADIANS(B8))*(1-COS(RADIANS(C8-C7))))))=0,1,2/(ACOS(MIN(1,MAX(-1,COS(RADIANS(B8-B7))-SIN(RADIANS(B7))*SIN(RADIANS(B8))*(1-COS(RADIANS(C8-C7)))))))*TAN((ACOS(MIN(1,MAX(-1,COS(RADIANS(B8-B7))-SIN(RADIANS(B7))*SIN(RADIANS(B8))*(1-COS(RADIANS(C8-C7)))))))/2))) -> 1200 | E8: =E7+(A8-A7)/2*(SIN(RADIANS(B7))*COS(RADIANS(C7))+SIN(RADIANS(B8))*COS(RADIANS(C8)))*(IF(ACOS(MIN(1,MAX(-1,COS(RADIANS(B8-B7))-SIN(RADIANS(B7))*SIN(RADIANS(B8))*(1-COS(RADIANS(C8-C7))))))=0,1,2/(ACOS(MIN(1,MAX(-1,COS(RADIANS(B8-B7))-SIN(RADIANS(B7))*SIN(RADIANS(B8))*(1-COS(RADIANS(C8-C7)))))))*TAN((ACOS(MIN(1,MAX(-1,COS(RADIANS(B8-B7))-SIN(RADIANS(B7))*SIN(RADIANS(B8))*(1-COS(RADIANS(C8-C7)))))))/2))) -> 0 | F8: =F7+(A8-A7)/2*(SIN(RADIANS(B7))*SIN(RADIANS(C7))+SIN(RADIANS(B8))*SIN(RADIANS(C8)))*(IF(ACOS(MIN(1,MAX(-1,COS(RADIANS(B8-B7))-SIN(RADIANS(B7))*SIN(RADIANS(B8))*(1-COS(RADIANS(C8-C7))))))=0,1,2/(ACOS(MIN(1,MAX(-1,COS(RADIANS(B8-B7))-SIN(RADIANS(B7))*SIN(RADIANS(B8))*(1-COS(RADIANS(C8-C7)))))))*TAN((ACOS(MIN(1,MAX(-1,COS(RADIANS(B8-B7))-SIN(RADIANS(B7))*SIN(RADIANS(B8))*(1-COS(RADIANS(C8-C7)))))))/2))) -> 0 | G8: =IF(H8=0,0,DEGREES(ACOS(MIN(1,MAX(-1,COS(RADIANS(B8-B7))-SIN(RADIANS(B7))*SIN(RADIANS(B8))*(1-COS(RADIANS(C8-C7)))))))*100/H8) -> 0 | H8: =A8-A7 -> 200 | I8: =J8*COS(RADIANS(K8-Well_Data!$B$68)) -> 0 | J8: =SQRT(E8^2+F8^2) -> 0 | K8: =IF(J8=0,0,MOD(DEGREES(ATAN2(E8,F8)),360)) -> 0
A9: 1400 | B9: 0 | C9: 0 | D9: =D8+(A9-A8)/2*(COS(RADIANS(B8))+COS(RADIANS(B9)))*(IF(ACOS(MIN(1,MAX(-1,COS(RADIANS(B9-B8))-SIN(RADIANS(B8))*SIN(RADIANS(B9))*(1-COS(RADIANS(C9-C8))))))=0,1,2/(ACOS(MIN(1,MAX(-1,COS(RADIANS(B9-B8))-SIN(RADIANS(B8))*SIN(RADIANS(B9))*(1-COS(RADIANS(C9-C8)))))))*TAN((ACOS(MIN(1,MAX(-1,COS(RADIANS(B9-B8))-SIN(RADIANS(B8))*SIN(RADIANS(B9))*(1-COS(RADIANS(C9-C8)))))))/2))) -> 1400 | E9: =E8+(A9-A8)/2*(SIN(RADIANS(B8))*COS(RADIANS(C8))+SIN(RADIANS(B9))*COS(RADIANS(C9)))*(IF(ACOS(MIN(1,MAX(-1,COS(RADIANS(B9-B8))-SIN(RADIANS(B8))*SIN(RADIANS(B9))*(1-COS(RADIANS(C9-C8))))))=0,1,2/(ACOS(MIN(1,MAX(-1,COS(RADIANS(B9-B8))-SIN(RADIANS(B8))*SIN(RADIANS(B9))*(1-COS(RADIANS(C9-C8)))))))*TAN((ACOS(MIN(1,MAX(-1,COS(RADIANS(B9-B8))-SIN(RADIANS(B8))*SIN(RADIANS(B9))*(1-COS(RADIANS(C9-C8)))))))/2))) -> 0 | F9: =F8+(A9-A8)/2*(SIN(RADIANS(B8))*SIN(RADIANS(C8))+SIN(RADIANS(B9))*SIN(RADIANS(C9)))*(IF(ACOS(MIN(1,MAX(-1,COS(RADIANS(B9-B8))-SIN(RADIANS(B8))*SIN(RADIANS(B9))*(1-COS(RADIANS(C9-C8))))))=0,1,2/(ACOS(MIN(1,MAX(-1,COS(RADIANS(B9-B8))-SIN(RADIANS(B8))*SIN(RADIANS(B9))*(1-COS(RADIANS(C9-C8)))))))*TAN((ACOS(MIN(1,MAX(-1,COS(RADIANS(B9-B8))-SIN(RADIANS(B8))*SIN(RADIANS(B9))*(1-COS(RADIANS(C9-C8)))))))/2))) -> 0 | G9: =IF(H9=0,0,DEGREES(ACOS(MIN(1,MAX(-1,COS(RADIANS(B9-B8))-SIN(RADIANS(B8))*SIN(RADIANS(B9))*(1-COS(RADIANS(C9-C8)))))))*100/H9) -> 0 | H9: =A9-A8 -> 200 | I9: =J9*COS(RADIANS(K9-Well_Data!$B$68)) -> 0 | J9: =SQRT(E9^2+F9^2) -> 0 | K9: =IF(J9=0,0,MOD(DEGREES(ATAN2(E9,F9)),360)) -> 0
A10: 1600 | B10: 0 | C10: 0 | D10: =D9+(A10-A9)/2*(COS(RADIANS(B9))+COS(RADIANS(B10)))*(IF(ACOS(MIN(1,MAX(-1,COS(RADIANS(B10-B9))-SIN(RADIANS(B9))*SIN(RADIANS(B10))*(1-COS(RADIANS(C10-C9))))))=0,1,2/(ACOS(MIN(1,MAX(-1,COS(RADIANS(B10-B9))-SIN(RADIANS(B9))*SIN(RADIANS(B10))*(1-COS(RADIANS(C10-C9)))))))*TAN((ACOS(MIN(1,MAX(-1,COS(RADIANS(B10-B9))-SIN(RADIANS(B9))*SIN(RADIANS(B10))*(1-COS(RADIANS(C10-C9)))))))/2))) -> 1600 | E10: =E9+(A10-A9)/2*(SIN(RADIANS(B9))*COS(RADIANS(C9))+SIN(RADIANS(B10))*COS(RADIANS(C10)))*(IF(ACOS(MIN(1,MAX(-1,COS(RADIANS(B10-B9))-SIN(RADIANS(B9))*SIN(RADIANS(B10))*(1-COS(RADIANS(C10-C9))))))=0,1,2/(ACOS(MIN(1,MAX(-1,COS(RADIANS(B10-B9))-SIN(RADIANS(B9))*SIN(RADIANS(B10))*(1-COS(RADIANS(C10-C9)))))))*TAN((ACOS(MIN(1,MAX(-1,COS(RADIANS(B10-B9))-SIN(RADIANS(B9))*SIN(RADIANS(B10))*(1-COS(RADIANS(C10-C9)))))))/2))) -> 0 | F10: =F9+(A10-A9)/2*(SIN(RADIANS(B9))*SIN(RADIANS(C9))+SIN(RADIANS(B10))*SIN(RADIANS(C10)))*(IF(ACOS(MIN(1,MAX(-1,COS(RADIANS(B10-B9))-SIN(RADIANS(B9))*SIN(RADIANS(B10))*(1-COS(RADIANS(C10-C9))))))=0,1,2/(ACOS(MIN(1,MAX(-1,COS(RADIANS(B10-B9))-SIN(RADIANS(B9))*SIN(RADIANS(B10))*(1-COS(RADIANS(C10-C9)))))))*TAN((ACOS(MIN(1,MAX(-1,COS(RADIANS(B10-B9))-SIN(RADIANS(B9))*SIN(RADIANS(B10))*(1-COS(RADIANS(C10-C9)))))))/2))) -> 0 | G10: =IF(H10=0,0,DEGREES(ACOS(MIN(1,MAX(-1,COS(RADIANS(B10-B9))-SIN(RADIANS(B9))*SIN(RADIANS(B10))*(1-COS(RADIANS(C10-C9)))))))*100/H10) -> 0 | H10: =A10-A9 -> 200 | I10: =J10*COS(RADIANS(K10-Well_Data!$B$68)) -> 0 | J10: =SQRT(E10^2+F10^2) -> 0 | K10: =IF(J10=0,0,MOD(DEGREES(ATAN2(E10,F10)),360)) -> 0
A11: 1800 | B11: 0 | C11: 0 | D11: =D10+(A11-A10)/2*(COS(RADIANS(B10))+COS(RADIANS(B11)))*(IF(ACOS(MIN(1,MAX(-1,COS(RADIANS(B11-B10))-SIN(RADIANS(B10))*SIN(RADIANS(B11))*(1-COS(RADIANS(C11-C10))))))=0,1,2/(ACOS(MIN(1,MAX(-1,COS(RADIANS(B11-B10))-SIN(RADIANS(B10))*SIN(RADIANS(B11))*(1-COS(RADIANS(C11-C10)))))))*TAN((ACOS(MIN(1,MAX(-1,COS(RADIANS(B11-B10))-SIN(RADIANS(B10))*SIN(RADIANS(B11))*(1-COS(RADIANS(C11-C10)))))))/2))) -> 1800 | E11: =E10+(A11-A10)/2*(SIN(RADIANS(B10))*COS(RADIANS(C10))+SIN(RADIANS(B11))*COS(RADIANS(C11)))*(IF(ACOS(MIN(1,MAX(-1,COS(RADIANS(B11-B10))-SIN(RADIANS(B10))*SIN(RADIANS(B11))*(1-COS(RADIANS(C11-C10))))))=0,1,2/(ACOS(MIN(1,MAX(-1,COS(RADIANS(B11-B10))-SIN(RADIANS(B10))*SIN(RADIANS(B11))*(1-COS(RADIANS(C11-C10)))))))*TAN((ACOS(MIN(1,MAX(-1,COS(RADIANS(B11-B10))-SIN(RADIANS(B10))*SIN(RADIANS(B11))*(1-COS(RADIANS(C11-C10)))))))/2))) -> 0 | F11: =F10+(A11-A10)/2*(SIN(RADIANS(B10))*SIN(RADIANS(C10))+SIN(RADIANS(B11))*SIN(RADIANS(C11)))*(IF(ACOS(MIN(1,MAX(-1,COS(RADIANS(B11-B10))-SIN(RADIANS(B10))*SIN(RADIANS(B11))*(1-COS(RADIANS(C11-C10))))))=0,1,2/(ACOS(MIN(1,MAX(-1,COS(RADIANS(B11-B10))-SIN(RADIANS(B10))*SIN(RADIANS(B11))*(1-COS(RADIANS(C11-C10)))))))*TAN((ACOS(MIN(1,MAX(-1,COS(RADIANS(B11-B10))-SIN(RADIANS(B10))*SIN(RADIANS(B11))*(1-COS(RADIANS(C11-C10)))))))/2))) -> 0 | G11: =IF(H11=0,0,DEGREES(ACOS(MIN(1,MAX(-1,COS(RADIANS(B11-B10))-SIN(RADIANS(B10))*SIN(RADIANS(B11))*(1-COS(RADIANS(C11-C10)))))))*100/H11) -> 0 | H11: =A11-A10 -> 200 | I11: =J11*COS(RADIANS(K11-Well_Data!$B$68)) -> 0 | J11: =SQRT(E11^2+F11^2) -> 0 | K11: =IF(J11=0,0,MOD(DEGREES(ATAN2(E11,F11)),360)) -> 0
A12: 2000 | B12: 0 | C12: 142 | D12: =D11+(A12-A11)/2*(COS(RADIANS(B11))+COS(RADIANS(B12)))*(IF(ACOS(MIN(1,MAX(-1,COS(RADIANS(B12-B11))-SIN(RADIANS(B11))*SIN(RADIANS(B12))*(1-COS(RADIANS(C12-C11))))))=0,1,2/(ACOS(MIN(1,MAX(-1,COS(RADIANS(B12-B11))-SIN(RADIANS(B11))*SIN(RADIANS(B12))*(1-COS(RADIANS(C12-C11)))))))*TAN((ACOS(MIN(1,MAX(-1,COS(RADIANS(B12-B11))-SIN(RADIANS(B11))*SIN(RADIANS(B12))*(1-COS(RADIANS(C12-C11)))))))/2))) -> 2000 | E12: =E11+(A12-A11)/2*(SIN(RADIANS(B11))*COS(RADIANS(C11))+SIN(RADIANS(B12))*COS(RADIANS(C12)))*(IF(ACOS(MIN(1,MAX(-1,COS(RADIANS(B12-B11))-SIN(RADIANS(B11))*SIN(RADIANS(B12))*(1-COS(RADIANS(C12-C11))))))=0,1,2/(ACOS(MIN(1,MAX(-1,COS(RADIANS(B12-B11))-SIN(RADIANS(B11))*SIN(RADIANS(B12))*(1-COS(RADIANS(C12-C11)))))))*TAN((ACOS(MIN(1,MAX(-1,COS(RADIANS(B12-B11))-SIN(RADIANS(B11))*SIN(RADIANS(B12))*(1-COS(RADIANS(C12-C11)))))))/2))) -> 0 | F12: =F11+(A12-A11)/2*(SIN(RADIANS(B11))*SIN(RADIANS(C11))+SIN(RADIANS(B12))*SIN(RADIANS(C12)))*(IF(ACOS(MIN(1,MAX(-1,COS(RADIANS(B12-B11))-SIN(RADIANS(B11))*SIN(RADIANS(B12))*(1-COS(RADIANS(C12-C11))))))=0,1,2/(ACOS(MIN(1,MAX(-1,COS(RADIANS(B12-B11))-SIN(RADIANS(B11))*SIN(RADIANS(B12))*(1-COS(RADIANS(C12-C11)))))))*TAN((ACOS(MIN(1,MAX(-1,COS(RADIANS(B12-B11))-SIN(RADIANS(B11))*SIN(RADIANS(B12))*(1-COS(RADIANS(C12-C11)))))))/2))) -> 0 | G12: =IF(H12=0,0,DEGREES(ACOS(MIN(1,MAX(-1,COS(RADIANS(B12-B11))-SIN(RADIANS(B11))*SIN(RADIANS(B12))*(1-COS(RADIANS(C12-C11)))))))*100/H12) -> 0 | H12: =A12-A11 -> 200 | I12: =J12*COS(RADIANS(K12-Well_Data!$B$68)) -> 0 | J12: =SQRT(E12^2+F12^2) -> 0 | K12: =IF(J12=0,0,MOD(DEGREES(ATAN2(E12,F12)),360)) -> 0
A13: 2030 | B13: 0.75 | C13: 141.94 | D13: =D12+(A13-A12)/2*(COS(RADIANS(B12))+COS(RADIANS(B13)))*(IF(ACOS(MIN(1,MAX(-1,COS(RADIANS(B13-B12))-SIN(RADIANS(B12))*SIN(RADIANS(B13))*(1-COS(RADIANS(C13-C12))))))=0,1,2/(ACOS(MIN(1,MAX(-1,COS(RADIANS(B13-B12))-SIN(RADIANS(B12))*SIN(RADIANS(B13))*(1-COS(RADIANS(C13-C12)))))))*TAN((ACOS(MIN(1,MAX(-1,COS(RADIANS(B13-B12))-SIN(RADIANS(B12))*SIN(RADIANS(B13))*(1-COS(RADIANS(C13-C12)))))))/2))) -> 2029.9991 | E13: =E12+(A13-A12)/2*(SIN(RADIANS(B12))*COS(RADIANS(C12))+SIN(RADIANS(B13))*COS(RADIANS(C13)))*(IF(ACOS(MIN(1,MAX(-1,COS(RADIANS(B13-B12))-SIN(RADIANS(B12))*SIN(RADIANS(B13))*(1-COS(RADIANS(C13-C12))))))=0,1,2/(ACOS(MIN(1,MAX(-1,COS(RADIANS(B13-B12))-SIN(RADIANS(B12))*SIN(RADIANS(B13))*(1-COS(RADIANS(C13-C12)))))))*TAN((ACOS(MIN(1,MAX(-1,COS(RADIANS(B13-B12))-SIN(RADIANS(B12))*SIN(RADIANS(B13))*(1-COS(RADIANS(C13-C12)))))))/2))) -> -0.15459667 | F13: =F12+(A13-A12)/2*(SIN(RADIANS(B12))*SIN(RADIANS(C12))+SIN(RADIANS(B13))*SIN(RADIANS(C13)))*(IF(ACOS(MIN(1,MAX(-1,COS(RADIANS(B13-B12))-SIN(RADIANS(B12))*SIN(RADIANS(B13))*(1-COS(RADIANS(C13-C12))))))=0,1,2/(ACOS(MIN(1,MAX(-1,COS(RADIANS(B13-B12))-SIN(RADIANS(B12))*SIN(RADIANS(B13))*(1-COS(RADIANS(C13-C12)))))))*TAN((ACOS(MIN(1,MAX(-1,COS(RADIANS(B13-B12))-SIN(RADIANS(B12))*SIN(RADIANS(B13))*(1-COS(RADIANS(C13-C12)))))))/2))) -> 0.12104508 | G13: =IF(H13=0,0,DEGREES(ACOS(MIN(1,MAX(-1,COS(RADIANS(B13-B12))-SIN(RADIANS(B12))*SIN(RADIANS(B13))*(1-COS(RADIANS(C13-C12)))))))*100/H13) -> 2.5 | H13: =A13-A12 -> 30 | I13: =J13*COS(RADIANS(K13-Well_Data!$B$68)) -> 0.19621984 | J13: =SQRT(E13^2+F13^2) -> 0.19634674 | K13: =IF(J13=0,0,MOD(DEGREES(ATAN2(E13,F13)),360)) -> 141.94
A14: 2060 | B14: 1.5 | C14: 142.03 | D14: =D13+(A14-A13)/2*(COS(RADIANS(B13))+COS(RADIANS(B14)))*(IF(ACOS(MIN(1,MAX(-1,COS(RADIANS(B14-B13))-SIN(RADIANS(B13))*SIN(RADIANS(B14))*(1-COS(RADIANS(C14-C13))))))=0,1,2/(ACOS(MIN(1,MAX(-1,COS(RADIANS(B14-B13))-SIN(RADIANS(B13))*SIN(RADIANS(B14))*(1-COS(RADIANS(C14-C13)))))))*TAN((ACOS(MIN(1,MAX(-1,COS(RADIANS(B14-B13))-SIN(RADIANS(B13))*SIN(RADIANS(B14))*(1-COS(RADIANS(C14-C13)))))))/2))) -> 2059.9931 | E14: =E13+(A14-A13)/2*(SIN(RADIANS(B13))*COS(RADIANS(C13))+SIN(RADIANS(B14))*COS(RADIANS(C14)))*(IF(ACOS(MIN(1,MAX(-1,COS(RADIANS(B14-B13))-SIN(RADIANS(B13))*SIN(RADIANS(B14))*(1-COS(RADIANS(C14-C13))))))=0,1,2/(ACOS(MIN(1,MAX(-1,COS(RADIANS(B14-B13))-SIN(RADIANS(B13))*SIN(RADIANS(B14))*(1-COS(RADIANS(C14-C13)))))))*TAN((ACOS(MIN(1,MAX(-1,COS(RADIANS(B14-B13))-SIN(RADIANS(B13))*SIN(RADIANS(B14))*(1-COS(RADIANS(C14-C13)))))))/2))) -> -0.61874004 | F14: =F13+(A14-A13)/2*(SIN(RADIANS(B13))*SIN(RADIANS(C13))+SIN(RADIANS(B14))*SIN(RADIANS(C14)))*(IF(ACOS(MIN(1,MAX(-1,COS(RADIANS(B14-B13))-SIN(RADIANS(B13))*SIN(RADIANS(B14))*(1-COS(RADIANS(C14-C13))))))=0,1,2/(ACOS(MIN(1,MAX(-1,COS(RADIANS(B14-B13))-SIN(RADIANS(B13))*SIN(RADIANS(B14))*(1-COS(RADIANS(C14-C13)))))))*TAN((ACOS(MIN(1,MAX(-1,COS(RADIANS(B14-B13))-SIN(RADIANS(B13))*SIN(RADIANS(B14))*(1-COS(RADIANS(C14-C13)))))))/2))) -> 0.48367365 | G14: =IF(H14=0,0,DEGREES(ACOS(MIN(1,MAX(-1,COS(RADIANS(B14-B13))-SIN(RADIANS(B13))*SIN(RADIANS(B14))*(1-COS(RADIANS(C14-C13)))))))*100/H14) -> 2.5000062 | H14: =A14-A13 -> 30 | I14: =J14*COS(RADIANS(K14-Well_Data!$B$68)) -> 0.78486744 | J14: =SQRT(E14^2+F14^2) -> 0.78535306 | K14: =IF(J14=0,0,MOD(DEGREES(ATAN2(E14,F14)),360)) -> 141.985
... A158: 12460 | B158: 34.62 | C158: 145.93 | D158: =D157+(A158-A157)/2*(COS(RADIANS(B157))+COS(RADIANS(B158)))*(IF(ACOS(MIN(1,MAX(-1,COS(RADIANS(B158-B157))-SIN(RADIANS(B157))*SIN(RADIANS(B158))*(1-COS(RADIANS(C158-C157))))))=0,1,2/(ACOS(MIN(1,MAX(-1,COS(RADIANS(B158-B157))-SIN(RADIANS(B157))*SIN(RADIANS(B158))*(1-COS(RADIANS(C158-C157)))))))*TAN((ACOS(MIN(1,MAX(-1,COS(RADIANS(B158-B157))-SIN(RADIANS(B157))*SIN(RADIANS(B158))*(1-COS(RADIANS(C158-C157)))))))/2))) -> 10753.654 | E158: =E157+(A158-A157)/2*(SIN(RADIANS(B157))*COS(RADIANS(C157))+SIN(RADIANS(B158))*COS(RADIANS(C158)))*(IF(ACOS(MIN(1,MAX(-1,COS(RADIANS(B158-B157))-SIN(RADIANS(B157))*SIN(RADIANS(B158))*(1-COS(RADIANS(C158-C157))))))=0,1,2/(ACOS(MIN(1,MAX(-1,COS(RADIANS(B158-B157))-SIN(RADIANS(B157))*SIN(RADIANS(B158))*(1-COS(RADIANS(C158-C157)))))))*TAN((ACOS(MIN(1,MAX(-1,COS(RADIANS(B158-B157))-SIN(RADIANS(B157))*SIN(RADIANS(B158))*(1-COS(RADIANS(C158-C157)))))))/2))) -> -4547.2434 | F158: =F157+(A158-A157)/2*(SIN(RADIANS(B157))*SIN(RADIANS(C157))+SIN(RADIANS(B158))*SIN(RADIANS(C158)))*(IF(ACOS(MIN(1,MAX(-1,COS(RADIANS(B158-B157))-SIN(RADIANS(B157))*SIN(RADIANS(B158))*(1-COS(RADIANS(C158-C157))))))=0,1,2/(ACOS(MIN(1,MAX(-1,COS(RADIANS(B158-B157))-SIN(RADIANS(B157))*SIN(RADIANS(B158))*(1-COS(RADIANS(C158-C157)))))))*TAN((ACOS(MIN(1,MAX(-1,COS(RADIANS(B158-B157))-SIN(RADIANS(B157))*SIN(RADIANS(B158))*(1-COS(RADIANS(C158-C157)))))))/2))) -> 3242.9837 | G158: =IF(H158=0,0,DEGREES(ACOS(MIN(1,MAX(-1,COS(RADIANS(B158-B157))-SIN(RADIANS(B157))*SIN(RADIANS(B158))*(1-COS(RADIANS(C158-C157)))))))*100/H158) -> 0.63388272 | H158: =A158-A157 -> 39 | I158: =J158*COS(RADIANS(K158-Well_Data!$B$68)) -> 5584.9752 | J158: =SQRT(E158^2+F158^2) -> 5585.1917 | K158: =IF(J158=0,0,MOD(DEGREES(ATAN2(E158,F158)),360)) -> 144.50446
A160: TVD / Northing / Easting / DLS computed by minimum curvature from the MD, inclination and azimuth columns.

Sheet Volumes
A1: Item_No | B1: Description | C1: OD_in | D1: ID_in | E1: Top_Depth_ft | F1: Bottom_Depth_ft | G1: Ann_Len_OpenHole_ft | H1: Ann_Vol_OpenHole_bbl | I1: Ann_Len_InCasing_ft | J1: Ann_Vol_InCasing_bbl | K1: Internal_Cap_bbl_per_ft | L1: Internal_Len_ft | M1: Internal_Vol_bbl
A2: =Pipe_Tally!A2 -> 1 | B2: =Pipe_Tally!D2 -> 8-1/2in PDC bit, 5x13 nozzles | C2: =Pipe_Tally!F2 -> 8.5 | D2: =Pipe_Tally!G2 -> 3 | E2: =Pipe_Tally!L2 -> 12498.98 | F2: =Pipe_Tally!M2 -> 12500 | G2: =MAX(0,MIN(F2,Well_Data!$B$10)-MAX(E2,Well_Data!$B$23)) -> 1.02 | H2: =G2*(Well_Data!$B$26^2-C2^2)/1029.4 -> 0 | I2: =MAX(0,MIN(F2,Well_Data!$B$23)-E2) -> 0 | J2: =I2*(Well_Data!$B$25^2-C2^2)/1029.4 -> 0 | K2: =D2^2/1029.4 -> 0.0087429571 | L2: =F2-E2 -> 1.02 | M2: =K2*L2 -> 0.0089178162
A3: =Pipe_Tally!A3 -> 2 | B3: =Pipe_Tally!D3 -> 6-3/4in PD motor, 1.5 deg bent hsg | C3: =Pipe_Tally!F3 -> 6.75 | D3: =Pipe_Tally!G3 -> 3 | E3: =Pipe_Tally!L3 -> 12470.51 | F3: =Pipe_Tally!M3 -> 12498.98 | G3: =MAX(0,MIN(F3,Well_Data!$B$10)-MAX(E3,Well_Data!$B$23)) -> 28.47 | H3: =G3*(Well_Data!$B$26^2-C3^2)/1029.4 -> 0.73809319 | I3: =MAX(0,MIN(F3,Well_Data!$B$23)-E3) -> 0 | J3: =I3*(Well_Data!$B$25^2-C3^2)/1029.4 -> 0 | K3: =D3^2/1029.4 -> 0.0087429571 | L3: =F3-E3 -> 28.47 | M3: =K3*L3 -> 0.24891199
A4: =Pipe_Tally!A4 -> 3 | B4: =Pipe_Tally!D4 -> 8-1/4in near-bit stabilizer | C4: =Pipe_Tally!F4 -> 8.25 | D4: =Pipe_Tally!G4 -> 2.813 | E4: =Pipe_Tally!L4 -> 12464.99 | F4: =Pipe_Tally!M4 -> 12470.51 | G4: =MAX(0,MIN(F4,Well_Data!$B$10)-MAX(E4,Well_Data!$B$23)) -> 5.52 | H4: =G4*(Well_Data!$B$26^2-C4^2)/1029.4 -> 0.022454828 | I4: =MAX(0,MIN(F4,Well_Data!$B$23)-E4) -> 0 | J4: =I4*(Well_Data!$B$25^2-C4^2)/1029.4 -> 0 | K4: =D4^2/1029.4 -> 0.007686972 | L4: =F4-E4 -> 5.52 | M4: =K4*L4 -> 0.042432086
A5: =Pipe_Tally!A5 -> 4 | B5: =Pipe_Tally!D5 -> 6-3/4in MWD / gamma collar | C5: =Pipe_Tally!F5 -> 6.75 | D5: =Pipe_Tally!G5 -> 3.25 | E5: =Pipe_Tally!L5 -> 12433.81 | F5: =Pipe_Tally!M5 -> 12464.99 | G5: =MAX(0,MIN(F5,Well_Data!$B$10)-MAX(E5,Well_Data!$B$23)) -> 31.18 | H5: =G5*(Well_Data!$B$26^2-C5^2)/1029.4 -> 0.80835074 | I5: =MAX(0,MIN(F5,Well_Data!$B$23)-E5) -> 0 | J5: =I5*(Well_Data!$B$25^2-C5^2)/1029.4 -> 0 | K5: =D5^2/1029.4 -> 0.010260832 | L5: =F5-E5 -> 31.18 | M5: =K5*L5 -> 0.31993273
A6: =Pipe_Tally!A6 -> 5 | B6: =Pipe_Tally!D6 -> 6-3/4in non-mag drill collar | C6: =Pipe_Tally!F6 -> 6.75 | D6: =Pipe_Tally!G6 -> 2.813 | E6: =Pipe_Tally!L6 -> 12403.67 | F6: =Pipe_Tally!M6 -> 12433.81 | G6: =MAX(0,MIN(F6,Well_Data!$B$10)-MAX(E6,Well_Data!$B$23)) -> 30.14 | H6: =G6*(Well_Data!$B$26^2-C6^2)/1029.4 -> 0.78138843 | I6: =MAX(0,MIN(F6,Well_Data!$B$23)-E6) -> 0 | J6: =I6*(Well_Data!$B$25^2-C6^2)/1029.4 -> 0 | K6: =D6^2/1029.4 -> 0.007686972 | L6: =F6-E6 -> 30.14 | M6: =K6*L6 -> 0.23168534
A7: =Pipe_Tally!A7 -> 6 | B7: =Pipe_Tally!D7 -> 8-1/4in string stabilizer | C7: =Pipe_Tally!F7 -> 8.25 | D7: =Pipe_Tally!G7 -> 2.813 | E7: =Pipe_Tally!L7 -> 12398.29 | F7: =Pipe_Tally!M7 -> 12403.67 | G7: =MAX(0,MIN(F7,Well_Data!$B$10)-MAX(E7,Well_Data!$B$23)) -> 5.38 | H7: =G7*(Well_Data!$B$26^2-C7^2)/1029.4 -> 0.021885322 | I7: =MAX(0,MIN(F7,Well_Data!$B$23)-E7) -> 0 | J7: =I7*(Well_Data!$B$25^2-C7^2)/1029.4 -> 0 | K7: =D7^2/1029.4 -> 0.007686972 | L7: =F7-E7 -> 5.38 | M7: =K7*L7 -> 0.041355909
A8: =Pipe_Tally!A8 -> 7 | B8: =Pipe_Tally!D8 -> 6-3/4in drill collar #1 | C8: =Pipe_Tally!F8 -> 6.75 | D8: =Pipe_Tally!G8 -> 2.813 | E8: =Pipe_Tally!L8 -> 12367.89 | F8: =Pipe_Tally!M8 -> 12398.29 | G8: =MAX(0,MIN(F8,Well_Data!$B$10)-MAX(E8,Well_Data!$B$23)) -> 30.4 | H8: =G8*(Well_Data!$B$26^2-C8^2)/1029.4 -> 0.78812901 | I8: =MAX(0,MIN(F8,Well_Data!$B$23)-E8) -> 0 | J8: =I8*(Well_Data!$B$25^2-C8^2)/1029.4 -> 0 | K8: =D8^2/1029.4 -> 0.007686972 | L8: =F8-E8 -> 30.4 | M8: =K8*L8 -> 0.23368395
A9: =Pipe_Tally!A9 -> 8 | B9: =Pipe_Tally!D9 -> 6-3/4in drill collar #2 | C9: =Pipe_Tally!F9 -> 6.75 | D9: =Pipe_Tally!G9 -> 2.813 | E9: =Pipe_Tally!L9 -> 12337.47 | F9: =Pipe_Tally!M9 -> 12367.89 | G9: =MAX(0,MIN(F9,Well_Data!$B$10)-MAX(E9,Well_Data!$B$23)) -> 30.42 | H9: =G9*(Well_Data!$B$26^2-C9^2)/1029.4 -> 0.78864751 | I9: =MAX(0,MIN(F9,Well_Data!$B$23)-E9) -> 0 | J9: =I9*(Well_Data!$B$25^2-C9^2)/1029.4 -> 0 | K9: =D9^2/1029.4 -> 0.007686972 | L9: =F9-E9 -> 30.42 | M9: =K9*L9 -> 0.23383769
A10: =Pipe_Tally!A10 -> 9 | B10: =Pipe_Tally!D10 -> 6-3/4in drill collar #3 | C10: =Pipe_Tally!F10 -> 6.75 | D10: =Pipe_Tally!G10 -> 2.813 | E10: =Pipe_Tally!L10 -> 12307.25 | F10: =Pipe_Tally!M10 -> 12337.47 | G10: =MAX(0,MIN(F10,Well_Data!$B$10)-MAX(E10,Well_Data!$B$23)) -> 30.22 | H10: =G10*(Well_Data!$B$26^2-C10^2)/1029.4 -> 0.78346245 | I10: =MAX(0,MIN(F10,Well_Data!$B$23)-E10) -> 0 | J10: =I10*(Well_Data!$B$25^2-C10^2)/1029.4 -> 0 | K10: =D10^2/1029.4 -> 0.007686972 | L10: =F10-E10 -> 30.22 | M10: =K10*L10 -> 0.23230029
A11: =Pipe_Tally!A11 -> 10 | B11: =Pipe_Tally!D11 -> 6-3/4in drill collar #4 | C11: =Pipe_Tally!F11 -> 6.75 | D11: =Pipe_Tally!G11 -> 2.813 | E11: =Pipe_Tally!L11 -> 12276.98 | F11: =Pipe_Tally!M11 -> 12307.25 | G11: =MAX(0,MIN(F11,Well_Data!$B$10)-MAX(E11,Well_Data!$B$23)) -> 30.27 | H11: =G11*(Well_Data!$B$26^2-C11^2)/1029.4 -> 0.78475872 | I11: =MAX(0,MIN(F11,Well_Data!$B$23)-E11) -> 0 | J11: =I11*(Well_Data!$B$25^2-C11^2)/1029.4 -> 0 | K11: =D11^2/1029.4 -> 0.007686972 | L11: =F11-E11 -> 30.27 | M11: =K11*L11 -> 0.23268464
A12: =Pipe_Tally!A12 -> 11 | B12: =Pipe_Tally!D12 -> 6-3/4in drill collar #5 | C12: =Pipe_Tally!F12 -> 6.75 | D12: =Pipe_Tally!G12 -> 2.813 | E12: =Pipe_Tally!L12 -> 12246.81 | F12: =Pipe_Tally!M12 -> 12276.98 | G12: =MAX(0,MIN(F12,Well_Data!$B$10)-MAX(E12,Well_Data!$B$23)) -> 30.17 | H12: =G12*(Well_Data!$B$26^2-C12^2)/1029.4 -> 0.78216619 | I12: =MAX(0,MIN(F12,Well_Data!$B$23)-E12) -> 0 | J12: =I12*(Well_Data!$B$25^2-C12^2)/1029.4 -> 0 | K12: =D12^2/1029.4 -> 0.007686972 | L12: =F12-E12 -> 30.17 | M12: =K12*L12 -> 0.23191595
A13: =Pipe_Tally!A13 -> 12 | B13: =Pipe_Tally!D13 -> 6-3/4in drill collar #6 | C13: =Pipe_Tally!F13 -> 6.75 | D13: =Pipe_Tally!G13 -> 2.813 | E13: =Pipe_Tally!L13 -> 12216.5 | F13: =Pipe_Tally!M13 -> 12246.81 | G13: =MAX(0,MIN(F13,Well_Data!$B$10)-MAX(E13,Well_Data!$B$23)) -> 30.31 | H13: =G13*(Well_Data!$B$26^2-C13^2)/1029.4 -> 0.78579573 | I13: =MAX(0,MIN(F13,Well_Data!$B$23)-E13) -> 0 | J13: =I13*(Well_Data!$B$25^2-C13^2)/1029.4 -> 0 | K13: =D13^2/1029.4 -> 0.007686972 | L13: =F13-E13 -> 30.31 | M13: =K13*L13 -> 0.23299212
... A406: =Pipe_Tally!A406 -> 405 | B406: =Pipe_Tally!D406 -> 5in drill pipe pup joint (5.07 ft) | C406: =Pipe_Tally!F406 -> 5 | D406: =Pipe_Tally!G406 -> 4.276 | E406: =Pipe_Tally!L406 -> 0 | F406: =Pipe_Tally!M406 -> 5.07 | G406: =MAX(0,MIN(F406,Well_Data!$B$10)-MAX(E406,Well_Data!$B$23)) -> 0 | H406: =G406*(Well_Data!$B$26^2-C406^2)/1029.4 -> 0 | I406: =MAX(0,MIN(F406,Well_Data!$B$23)-E406) -> 5.07 | J406: =I406*(Well_Data!$B$25^2-C406^2)/1029.4 -> 0.24803185 | K406: =D406^2/1029.4 -> 0.017761974 | L406: =F406-E406 -> 5.07 | M406: =K406*L406 -> 0.090053208
B407: TOTAL | H407: =SUM(H2:H406) -> 187.30696 | J407: =SUM(J2:J406) -> 401.15605 | M407: =SUM(M2:M406) -> 211.35461

Sheet Notes
A1: NOTES, ASSUMPTIONS AND LEGEND
A4: PURPOSE
A5: Synthetic test data for a well control kill planner. Nothing here came from a real well; the numbers are internally consistent so a correct planner should reproduce the expected results on the Well_Data sheet.
A7: LEGEND
A8: Blue text = hardcoded input value. Black text = formula. Every derived figure recalculates from the inputs, so you can change a value and watch it propagate.
A10: WELL
A11: Build-and-hold land well. Vertical to 2,000 ft MD, build at 2.5 deg/100 ft to 35 deg, hold to 12,500 ft MD. 13-3/8in surface shoe at 1,800 ft; 9-5/8in intermediate shoe at 8,200 ft; 8-1/2in open hole below. A survey station falls exactly on the intermediate shoe so shoe TVD needs no interpolation.
A13: SURVEY
A14: Minimum curvature. Stations every 200 ft while vertical, every 30 ft through the build, every 93 ft (one stand) in the tangent. Last station 12,460 ft MD; the bit is at 12,500 ft, so TVD at the bit is extended below the last station on the last inclination — the same thing a rig would do. Inclination and azimuth carry small station-to-station variation, so the tangent section is not a perfect 35.00 deg.
A16: TALLY
A17: 405 items, bit to surface, totalling exactly 12,500.00 ft. Individual joint lengths vary as measured lengths do. A 5.07 ft pup joint at the top makes the tally close on depth. Capacity = ID^2/1029.4. Displacement = (OD^2-ID^2)/1029.4, which is plain pipe body only and excludes tool joint steel — real closed-end displacement is slightly higher.
A19: KICK SCENARIO
... A31: TVD at the bit, TVD at the shoe, kill mud weight, ICP, FCP, MAASP, strokes from surface to bit, strokes from bit to shoe, and total circulation strokes. All are on the Well_Data sheet under EXPECTED KILL SHEET RESULTS.

Sheet Circulating_Key
A1: CIRCULATING ANSWER KEY — one circulation, wait and weight
A2: Output of an independent model (circulating.py), NOT of in-cell formulas. Read Notes_Circulating before trusting any of it.
A4: Figure | B4: Value | C4: Units | D4: Confidence / Note
A5: EXTERNALLY VALIDATED — the schedule method matches a published worked example
A6: Strokes to bit | B6: 1806 | C6: stk | D6: Volume/pump output. Also on Well_Data.
A7: ICP | B7: 800 | C7: psi | D7: Verified: matches the model endpoint exactly.
A8: FCP | B8: 342.4 | C8: psi | D8: Verified: matches the model endpoint exactly.
A9: Max deviation, rigorous schedule vs straight line | B9: 19.7 | C9: psi | D9: Genuine effect of the tapered string and the 35 deg hold — not rounding. Collapses to zero in a uniform vertical well, which is how it was checked against the published example.
A10: MODEL OUTPUT — self-consistent and endpoint-checked, but not externally sourced
A11: Strokes, gas top reaches surface | B11: 4156 | C11: stk | D11: Isothermal single-bubble assumption.
A12: Gas volume on arrival at surface | B12: 102 | C12: bbl | D12: Expansion ratio x4.64 from 22 bbl.
A13: Peak choke pressure | B13: 1526 | C13: psi | D13: Occurs as the gas top reaches surface, which is the textbook expectation.
A14: Strokes at peak choke pressure | B14: 4156 | C14: stk
A15: Peak casing shoe pressure | B15: 5375 | C15: psi | D15: Occurs at shut-in, before circulating. Falls thereafter, because kill mud entering the annulus raises hydrostatic below the shoe.
A16: Shoe margin at peak | B16: 582 | C16: psi | D16: Below formation integrity of 5957 psi. The shoe is not at risk in this scenario.
A17: Strokes, gas fully out | B17: 5028 | C17: stk
A18: Strokes, kill complete | B18: 6834 | C18: stk | D18: Kill mud back at surface, choke pressure zero.
A19: A DELIBERATE TRAP WORTH CHECKING
A20: Peak choke pressure vs MAASP | B20: 1526 psi vs 1357 psi MAASP | D20: Peak choke pressure EXCEEDS MAASP, yet the shoe stays 582 psi inside its limit. MAASP is computed with a full mud column; when gas occupies the annulus the surface pressure can pass MAASP without the shoe being over-pressured. An app that alarms on choke > MAASP here is being conservative, not correct — but it should say so rather than declare the kill infeasible.

Sheet Circulating_Profile
A1: Strokes | B1: Pumped_bbl | C1: DPP_Conventional_psi | D1: DPP_Rigorous_psi | E1: Choke_Pressure_psi | F1: Shoe_Pressure_psi | G1: Gas_Volume_bbl | H1: Gas_Pressure_psi | I1: Gas_Bottom_MD_ft | J1: Gas_Top_MD_ft | K1: Gas_Height_MD_ft | L1: Gas_At_Surface | M1: Gas_Venting | N1: Kill_Mud_String_MD_ft | O1: Kill_Mud_Annulus_MD_ft
A2: 0 | B2: 0 | C2: 800 | D2: 800 | E2: 775.4 | F2: 5375.3 | G2: 22 | H2: 7322.5 | I2: 12499 | J2: 11801.4 | K2: 697.6 | L2: 0 | M2: 0 | N2: 0
A3: 17 | B3: 2 | C3: 795.7 | D3: 795.2 | E3: 760.8 | F3: 5360.6 | G3: 22.13 | H3: 7279.7 | I3: 12417.2 | J3: 11755 | K3: 662.2 | L3: 0 | M3: 0 | N3: 112.6
A4: 34 | B4: 4 | C4: 791.3 | D4: 790.4 | E4: 746.1 | F4: 5345.9 | G4: 22.26 | H4: 7237 | I4: 12335.5 | J4: 11708.6 | K4: 626.9 | L4: 0 | M4: 0 | N4: 225.2
A5: 51 | B5: 6 | C5: 787 | D5: 785.6 | E5: 733.2 | F5: 5333.1 | G5: 22.39 | H5: 7196.7 | I5: 12258.4 | J5: 11662.3 | K5: 596.1 | L5: 0 | M5: 0 | N5: 337.8
A6: 68 | B6: 8 | C6: 782.7 | D6: 780.8 | E6: 720.5 | F6: 5320.3 | G6: 22.51 | H6: 7156.4 | I6: 12181.2 | J6: 11616 | K6: 565.2 | L6: 0 | M6: 0 | N6: 450.5
A7: 85 | B7: 10 | C7: 778.3 | D7: 776 | E7: 707.7 | F7: 5307.5 | G7: 22.64 | H7: 7116.2 | I7: 12104.1 | J7: 11569.6 | K7: 534.4 | L7: 0 | M7: 0 | N7: 563.1
A8: 103 | B8: 12 | C8: 774 | D8: 771.2 | E8: 695.3 | F8: 5295.1 | G8: 22.77 | H8: 7076.5 | I8: 12027.9 | J8: 11523.3 | K8: 504.6 | L8: 0 | M8: 0 | N8: 675.7
A9: 120 | B9: 14 | C9: 769.7 | D9: 766.4 | E9: 692.6 | F9: 5292.5 | G9: 22.85 | H9: 7049.2 | I9: 11975.7 | J9: 11477.8 | K9: 497.9 | L9: 0 | M9: 0 | N9: 788.3
A10: 137 | B10: 16 | C10: 765.4 | D10: 761.6 | E10: 693.4 | F10: 5293.3 | G10: 22.93 | H10: 7026.5 | I10: 11932.1 | J10: 11432.6 | K10: 499.5 | L10: 0 | M10: 0 | N10: 900.9
A11: 154 | B11: 18 | C11: 761 | D11: 756.8 | E11: 694.3 | F11: 5294.1 | G11: 23 | H11: 7003.6 | I11: 11888.6 | J11: 11387.4 | K11: 501.2 | L11: 0 | M11: 0 | N11: 1013.5
A12: 171 | B12: 20 | C12: 756.7 | D12: 752 | E12: 695.1 | F12: 5294.9 | G12: 23.08 | H12: 6980.9 | I12: 11845 | J12: 11342.2 | K12: 502.8 | L12: 0 | M12: 0 | N12: 1126.1
A13: 188 | B13: 22 | C13: 752.4 | D13: 747.2 | E13: 696 | F13: 5295.8 | G13: 23.15 | H13: 6958.1 | I13: 11801.4 | J13: 11297 | K13: 504.4 | L13: 0 | M13: 0 | N13: 1238.7
... A108: 1806 | B108: 211.33 | C108: 342.4 | D108: 342.4 | E108: 790.9 | F108: 5079.8 | G108: 33.39 | H108: 4824.4 | I108: 7708.9 | J108: 7026.3 | K108: 682.6 | L108: 0 | M108: 0 | N108: 12500
A109: 1811 | B109: 212 | C109: 342.4 | D109: 342.4 | E109: 790.5 | F109: 5078.9 | G109: 33.45 | H109: 4816.3 | I109: 7695.3 | J109: 7011.5 | K109: 683.7 | L109: 0 | M109: 0 | N109: 12500 | O109: 12473.2
A110: 1828 | B110: 214 | C110: 342.4 | D110: 342.4 | E110: 789.2 | F110: 5075.7 | G110: 33.62 | H110: 4791.9 | I110: 7654.4 | J110: 6967.1 | K110: 687.2 | L110: 0 | M110: 0 | N110: 12500 | O110: 12386.9
A111: 1846 | B111: 216 | C111: 342.4 | D111: 342.4 | E111: 788.2 | F111: 5072.9 | G111: 33.79 | H111: 4767.8 | I111: 7613.5 | J111: 6922.8 | K111: 690.7 | L111: 0 | M111: 0 | N111: 12500 | O111: 12309.7
A112: 1863 | B112: 218 | C112: 342.4 | D112: 342.4 | E112: 787.2 | F112: 5070 | G112: 33.96 | H112: 4743.7 | I112: 7572.6 | J112: 6878.4 | K112: 694.2 | L112: 0 | M112: 0 | N112: 12500 | O112: 12232.6
A113: 1880 | B113: 220 | C113: 342.4 | D113: 342.4 | E113: 786.2 | F113: 5067.2 | G113: 34.14 | H113: 4719.6 | I113: 7531.7 | J113: 6834 | K113: 697.8 | L113: 0 | M113: 0 | N113: 12500 | O113: 12155.4
A114: 1897 | B114: 222 | C114: 342.4 | D114: 342.4 | E114: 785.3 | F114: 5064.4 | G114: 34.31 | H114: 4695.5 | I114: 7490.8 | J114: 6789.5 | K114: 701.3 | L114: 0 | M114: 0 | N114: 12500 | O114: 12078.3
A115: 1914 | B115: 224 | C115: 342.4 | D115: 342.4 | E115: 784.5 | F115: 5061.7 | G115: 34.49 | H115: 4671.6 | I115: 7450 | J115: 6745 | K115: 704.9 | L115: 0 | M115: 0 | N115: 12500 | O115: 12004.9
A116: 1931 | B116: 226 | C116: 342.4 | D116: 342.4 | E116: 784.7 | F116: 5060.1 | G116: 34.66 | H116: 4648.8 | I116: 7409.1 | J116: 6700.7 | K116: 708.4 | L116: 0 | M116: 0 | N116: 12500 | O116: 11961.1
A117: 1948 | B117: 228 | C117: 342.4 | D117: 342.4 | E117: 784.9 | F117: 5058.5 | G117: 34.83 | H117: 4625.9 | I117: 7368.2 | J117: 6656.3 | K117: 711.9 | L117: 0 | M117: 0 | N117: 12500 | O117: 11917.6
A118: 1965 | B118: 230 | C118: 342.4 | D118: 342.4 | E118: 785.2 | F118: 5056.9 | G118: 35 | H118: 4603 | I118: 7327.3 | J118: 6611.9 | K118: 715.4 | L118: 0 | M118: 0 | N118: 12500 | O118: 11874
A119: 1982 | B119: 232 | C119: 342.4 | D119: 342.4 | E119: 785.5 | F119: 5055.3 | G119: 35.17 | H119: 4580.2 | I119: 7286.4 | J119: 6567.4 | K119: 719 | L119: 0 | M119: 0 | N119: 12500 | O119: 11830.4
A120: 1999 | B120: 234 | C120: 342.4 | D120: 342.4 | E120: 785.8 | F120: 5053.7 | G120: 35.35 | H120: 4557.3 | I120: 7245.6 | J120: 6522.9 | K120: 722.6 | L120: 0 | M120: 0 | N120: 12500 | O120: 11786.9
... A405: 6834 | B405: 799.79 | C405: 342.4 | D405: 342.4 | E405: 0 | F405: 4922.5 | G405: 0 | H405: 0 | I405: 0 | J405: 0 | K405: 0 | L405: 0 | M405: 0 | N405: 12500 | O405: 0
A407: Model output, not in-cell formulas. Reproduce with circulating.py. Every row satisfies constant bottomhole pressure to 0.0000 psi and closes the annular volume book exactly.

Sheet External_Validation
A1: EXTERNAL VALIDATION — drill pipe pressure schedule
A2: Second source: drillingformulas.com, 'Drill Pipe Pressure Schedule Calculation for Wait and Weight Well Control Method'. Its inputs and published table are reproduced verbatim in blue.
A4: PUBLISHED INPUTS
A5: Original mud weight | B5: 9.5 | C5: ppg
A6: Pump output | B6: 0.1 | C6: bbl/stk
A7: Depth (vertical, MD = TVD) | B7: 9000 | C7: ft
A8: Drill string capacity | B8: 0.0178 | C8: bbl/ft
A9: Surface line volume | B9: 15 | C9: bbl
A10: SIDPP | B10: 500 | C10: psi
A11: ICP | B11: 1600 | C11: psi
A12: Published KWM | B12: 10.6 | C12: ppg
A13: Published FCP | B13: 1227 | C13: psi
A15: DERIVED
A16: SCR | B16: =$B$11-$B$10 -> 1100 | C16: psi
A17: BHP | B17: =$B$10+0.052*$B$5*$B$7 -> 4946 | C17: psi
A18: Recomputed KWM | B18: =$B$5+$B$10/(0.052*$B$7) -> 10.568376 | C18: ppg
A19: String volume | B19: =$B$8*$B$7 -> 160.2 | C19: bbl
A20: Strokes to bit | B20: =$B$19/$B$6 -> 1602 | C20: stk
A21: Surface line strokes | B21: =$B$9/$B$6 -> 150 | C21: stk
A23: Strokes | B23: Published DPP (psi) | C23: Straight line (psi) | D23: Rigorous model (psi) | E23: Published - straight | F23: Straight - rigorous
A24: 150 | B24: 1600 | C24: =$B$11-($B$11-$B$13)*MIN(MAX(A24-$B$21,0),$B$20)/$B$20 -> 1600 | D24: =$B$17+($B$16+($B$13-$B$16)*MIN(MAX(A24-$B$21,0),$B$20)/$B$20)-(0.052*$B$12*(MIN(MAX(A24-$B$21,0),$B$20)/$B$20*$B$7)+0.052*$B$5*($B$7-(MIN(MAX(A24-$B$21,0),$B$20)/$B$20*$B$7))) -> 1600 | E24: =B24-C24 -> 0 | F24: =C24-D24 -> 0
A25: 350 | B25: 1554 | C25: =$B$11-($B$11-$B$13)*MIN(MAX(A25-$B$21,0),$B$20)/$B$20 -> 1553.4332 | D25: =$B$17+($B$16+($B$13-$B$16)*MIN(MAX(A25-$B$21,0),$B$20)/$B$20)-(0.052*$B$12*(MIN(MAX(A25-$B$21,0),$B$20)/$B$20*$B$7)+0.052*$B$5*($B$7-(MIN(MAX(A25-$B$21,0),$B$20)/$B$20*$B$7))) -> 1551.5855 | E25: =B25-C25 -> 0.56679151 | F25: =C25-D25 -> 1.8476904
A26: 550 | B26: 1506 | C26: =$B$11-($B$11-$B$13)*MIN(MAX(A26-$B$21,0),$B$20)/$B$20 -> 1506.8664 | D26: =$B$17+($B$16+($B$13-$B$16)*MIN(MAX(A26-$B$21,0),$B$20)/$B$20)-(0.052*$B$12*(MIN(MAX(A26-$B$21,0),$B$20)/$B$20*$B$7)+0.052*$B$5*($B$7-(MIN(MAX(A26-$B$21,0),$B$20)/$B$20*$B$7))) -> 1503.171 | E26: =B26-C26 -> -0.86641698 | F26: =C26-D26 -> 3.6953808
A27: 750 | B27: 1459 | C27: =$B$11-($B$11-$B$13)*MIN(MAX(A27-$B$21,0),$B$20)/$B$20 -> 1460.2996 | D27: =$B$17+($B$16+($B$13-$B$16)*MIN(MAX(A27-$B$21,0),$B$20)/$B$20)-(0.052*$B$12*(MIN(MAX(A27-$B$21,0),$B$20)/$B$20*$B$7)+0.052*$B$5*($B$7-(MIN(MAX(A27-$B$21,0),$B$20)/$B$20*$B$7))) -> 1454.7566 | E27: =B27-C27 -> -1.2996255 | F27: =C27-D27 -> 5.5430712
A28: 950 | B28: 1412 | C28: =$B$11-($B$11-$B$13)*MIN(MAX(A28-$B$21,0),$B$20)/$B$20 -> 1413.7328 | D28: =$B$17+($B$16+($B$13-$B$16)*MIN(MAX(A28-$B$21,0),$B$20)/$B$20)-(0.052*$B$12*(MIN(MAX(A28-$B$21,0),$B$20)/$B$20*$B$7)+0.052*$B$5*($B$7-(MIN(MAX(A28-$B$21,0),$B$20)/$B$20*$B$7))) -> 1406.3421 | E28: =B28-C28 -> -1.732834 | F28: =C28-D28 -> 7.3907615
A29: 1150 | B29: 1365 | C29: =$B$11-($B$11-$B$13)*MIN(MAX(A29-$B$21,0),$B$20)/$B$20 -> 1367.166 | D29: =$B$17+($B$16+($B$13-$B$16)*MIN(MAX(A29-$B$21,0),$B$20)/$B$20)-(0.052*$B$12*(MIN(MAX(A29-$B$21,0),$B$20)/$B$20*$B$7)+0.052*$B$5*($B$7-(MIN(MAX(A29-$B$21,0),$B$20)/$B$20*$B$7))) -> 1357.9276 | E29: =B29-C29 -> -2.1660424 | F29: =C29-D29 -> 9.2384519
A30: 1350 | B30: 1318 | C30: =$B$11-($B$11-$B$13)*MIN(MAX(A30-$B$21,0),$B$20)/$B$20 -> 1320.5993 | D30: =$B$17+($B$16+($B$13-$B$16)*MIN(MAX(A30-$B$21,0),$B$20)/$B$20)-(0.052*$B$12*(MIN(MAX(A30-$B$21,0),$B$20)/$B$20*$B$7)+0.052*$B$5*($B$7-(MIN(MAX(A30-$B$21,0),$B$20)/$B$20*$B$7))) -> 1309.5131 | E30: =B30-C30 -> -2.5992509 | F30: =C30-D30 -> 11.086142
A31: 1550 | B31: 1271 | C31: =$B$11-($B$11-$B$13)*MIN(MAX(A31-$B$21,0),$B$20)/$B$20 -> 1274.0325 | D31: =$B$17+($B$16+($B$13-$B$16)*MIN(MAX(A31-$B$21,0),$B$20)/$B$20)-(0.052*$B$12*(MIN(MAX(A31-$B$21,0),$B$20)/$B$20*$B$7)+0.052*$B$5*($B$7-(MIN(MAX(A31-$B$21,0),$B$20)/$B$20*$B$7))) -> 1261.0986 | E31: =B31-C31 -> -3.0324594 | F31: =C31-D31 -> 12.933833
A32: 1750 | B32: 1227 | C32: =$B$11-($B$11-$B$13)*MIN(MAX(A32-$B$21,0),$B$20)/$B$20 -> 1227.4657 | D32: =$B$17+($B$16+($B$13-$B$16)*MIN(MAX(A32-$B$21,0),$B$20)/$B$20)-(0.052*$B$12*(MIN(MAX(A32-$B$21,0),$B$20)/$B$20*$B$7)+0.052*$B$5*($B$7-(MIN(MAX(A32-$B$21,0),$B$20)/$B$20*$B$7))) -> 1212.6841 | E32: =B32-C32 -> -0.46566792 | F32: =C32-D32 -> 14.781523
